Workbook
Name NFL_Teams: 'Week-by-Week Games Table (2)'!$Q$2:$R$34

Sheet Standings
A1: POS | B1: Participant | C1: Score
A2: =RANK(C2,C:C) -> 1 | B2: Carrie | C2: =main!AG85 -> 13
A3: =RANK(C3,C:C) -> 2 | B3: Shelley | C3: =main!AG40 -> 11
A4: =RANK(C4,C:C) -> 2 | B4: John | C4: =main!AG130 -> 11
A5: =RANK(C5,C:C) -> 2 | B5: Zack | C5: =main!AG144 -> 11
A6: =RANK(C6,C:C) -> 5 | B6: Brian | C6: =main!AG42 -> 10
A7: =RANK(C7,C:C) -> 5 | B7: William | C7: =main!AG138 -> 10
A8: =RANK(C8,C:C) -> 5 | B8: Kyle | C8: =main!AG93 -> 10
A9: =RANK(C9,C:C) -> 8 | B9: Lisa B | C9: =main!AG128 -> 9
A10: =RANK(C10,C:C) -> 8 | B10: Colby | C10: =main!AG36 -> 9
A11: =RANK(C11,C:C) -> 8 | B11: Dave C | C11: =main!AG95 -> 9
A12: =RANK(C12,C:C) -> 8 | B12: Lori Lynn | C12: =main!AG30 -> 9
A13: =RANK(C13,C:C) -> 8 | B13: Kaleb | C13: =main!AG89 -> 9
A14: =RANK(C14,C:C) -> 8 | B14: Red Wing | C14: =main!AG136 -> 9
A15: =RANK(C15,C:C) -> 8 | B15: Grant | C15: =main!AG142 -> 9
A16: =RANK(C16,C:C) -> 15 | B16: SJay | C16: =main!AG32 -> 8
A17: =RANK(C17,C:C) -> 15 | B17: Frank | C17: =main!AG81 -> 8
A18: =RANK(C18,C:C) -> 15 | B18: Forrest | C18: =main!AG132 -> 8
A19: =RANK(C19,C:C) -> 15 | B19: Jesse | C19: =main!AG134 -> 8
A20: =RANK(C20,C:C) -> 15 | B20: Boots | C20: =main!AG34 -> 8
A21: =RANK(C21,C:C) -> 15 | B21: Tom | C21: =main!AG46 -> 8
A22: =RANK(C22,C:C) -> 15 | B22: Karen | C22: =main!AG48 -> 8
A23: =RANK(C23,C:C) -> 15 | B23: Al | C23: =main!AG87 -> 8
A24: =RANK(C24,C:C) -> 23 | B24: Theresa | C24: =main!AG97 -> 7
A25: =RANK(C25,C:C) -> 23 | B25: Tom C | C25: =main!AG83 -> 7
A26: =RANK(C26,C:C) -> 23 | B26: Robyn | C26: =main!AG91 -> 7
A27: =RANK(C27,C:C) -> 23 | B27: Joe | C27: =main!AG140 -> 7
A28: =RANK(C28,C:C) -> 23 | B28: Bloomers | C28: =main!AG44 -> 7
A29: =RANK(C29,C:C) -> 23 | B29: Chrissy | C29: =main!AG146 -> 7
A30: =RANK(C30,C:C) -> 29 | B30: Me | C30: =main!AG38 -> 6
A31: =RANK(C31,C:C) -> 30 | B31: Denise | C31: =main!AG79 -> 5

Sheet Scenarios
A1: SCENARIOS
B4: kc over philly
B5: 51 points 4-way tie | C5: lori lynn | D5: kaleb | E5: sjay | F5: red wing
B7: philly over kc
B8: 52 al | C8: 51 lori lynn/kaleb

Sheet Payouts
A1: 2025 payouts | B1: 180 pot | D1: 2026 | E1: paid/owed | F1: mailers | G1: form of payment | H1: delivery | I1: covering | J1: mailers | K1: notes | L1: address | M1: City | N1: Zip
A2: Al | B2: =PRODUCT(180,0.6) -> 108 | D2: Lori Lynn | E2: 12 | F2: 2 | G2: check | H2: mail | I2: - | J2: 1 | L2: P.O. Box 715 | M2: Warrenton | N2: 97146
A3: 2nd split | B3: =PRODUCT(180,0.4) -> 72 | D3: SJay | E3: 20 | G3: cash | H3: person | I3: Boots
A4: Lori Lynn / Kaleb | B4: =PRODUCT(72,0.5) -> 36 | D4: Colby | E4: 12 | F4: 2 | G4: check | H4: mail | I4: - | J4: 1
D5: Tom H | E5: 22 | F5: 2 | G5: cash | H5: mail | I5: Karen | J5: 1 | L5: 3112 89th St. NW | M5: Gig Harbor | N5: 98332-2123
D6: Brian | E6: 24 | F6: 4 | G6: check | H6: mail | I6: Shelley | J6: 2
D7: Norma Jean | E7: 15 | F7: 2 | G7: check | H7: mail | I7: - | J7: 1
D8: Denise | E8: 12 | F8: 2 | G8: cash | H8: mail | I8: - | J8: 1 | L8: 39873 Vista Rd | M8: Hemet | N8: 92543
D9: Frank | E9: 12 | F9: 2 | G9: cash | H9: person | I9: - | J9: 1
D10: Tom | E10: 20 | G10: cash | H10: person (David) | I10: Carrie | J10: 2
D11: Al | E11: 42 | F11: 2 | G11: check | H11: mail | I11: Kaleb Robyn Kyle | J11: 1 | L11: 800 NE E St. | M11: Willamina | N11: 97396-2722
D12: David | E12: 20 | G12: cash | H12: person | I12: Theresa | J12: 2
D13: Roberta | E13: 22 | F13: 2 | G13: check | H13: mail | I13: William | J13: 1 | L13: 8605 SW Rogue Ln | M13: Wilsonville | N13: 97070
D14: Forest | E14: 24 | F14: 4 | I14: Jesse | J14: 1 | L14: 896 SE 40th Ave | M14: Hillsboro | N14: 97123
D15: Lisa Brelinski | E15: 22 | F15: 2 | G15: check | I15: John | J15: 1 | L15: 8129 SE 141st Ave. | M15: Portland | N15: 97236
D16: Me | E16: 10 | G16: cash
D17: Joe | E17: 10 | G17: cash | H17: person | J17: 1
D18: Grant | E18: 32 | F18: 2 | G18: venmo | I18: zack/chrissy | J18: 1 | L18: 5095 Territorial Dr. | M18: West Linn | N18: 97068-3352
E19: =SUM(E2:E18) -> 331 | F19: =SUM(F2:F18) -> 28 | J19: =SUM(J2:J18) -> 18
E21: 300 savings | F21: 28 checking
E23: have 273 | F23: owed 24
F26: put 26 in checking
F27: 300 in savings

Sheet main
A2: Name | D2: SEPT | I2: OCT | N2: NOV | T2: DEC | X2: JAN | Z2: Totals
B3: 4 | C3: 5 | D3: 8 | E3: 14 | F3: 22 | G3: 29 | H3: 5 | I3: 12 | J3: 20 | K3: 26 | L3: 2 | M3: 9 | N3: 13 | O3: 23 | P3: 27 | Q3: 27 | R3: 7 | S3: 11 | T3: 18 | U3: 21 | V3: 25 | W3: tbd | X3: tbd | Y3: tbd
A4: Gm# | B4: 1 | C4: 2 | D4: 3 | E4: 4 | F4: 5 | G4: 6 | H4: 7 | I4: 8 | J4: 9 | K4: 10 | L4: 11 | M4: 12 | N4: 13 | O4: 14 | P4: 15 | Q4: 16 | R4: 17 | S4: 18 | T4: 19 | U4: 20 | V4: 21 | W4: 22 | X4: 23 | Y4: 24
A5: Lori Lynn | B5: PHI | C5: KC | D5: MIN | E5: LAR | F5: BAL | G5: DEN | H5: IND | I5: PIT | J5: HOU | K5: TB | L5: NYG | M5: BUF | N5: NYJ | O5: JAX | P5: DET | Q5: KC | R5: PIT | S5: TB | T5: LAR | U5: TB | V5: DAL | W5: DEN | X5: JAX | Y5: SEA | Z5: =SUM(B6:Y6) -> 9
B6: =IF(B25="Philadelphia Eagles",1,0) -> 1 | C6: =IF(C25="Kansas City Chiefs",1,0) -> 0 | D6: =IF(D25="Minnesota Vikings",1,0) -> 1 | E6: =IF(E25="Los Angeles Rams",1,0) -> 1 | F6: =IF(F25="Baltimore Ravens",1,0) -> 0 | G6: =IF(G25="Denver Broncos",1,0) -> 1 | H6: =IF(H25="Indianapolis Colts",1,0) -> 1 | I6: =IF(I25="Pittsburgh Steelers",1,0) -> 1 | J6: =IF(J25="Houston Texans",1,0) -> 0 | K6: =IF(K25="Tampa Bay Buccaneers",1,0) -> 1 | L6: =IF(L25="New York Giants",1,0) -> 0 | M6: =IF(M25="Buffalo Bills",1,0) -> 0 | N6: =IF(N25="New York Jets",1,0) -> 0 | O6: =IF(O25="Jacksonville Jaguars",1,0) -> 1 | P6: =IF(P25="Detroit Lions",1,0) -> 0 | Q6: =IF(Q25="Kansas City Chiefs",1,0) -> 0 | R6: =IF(R25="Pittsburgh Steelers",1,0) -> 1 | S6: =IF(S25="Tampa Bay Buccaneers",1,0) -> 0 | T6: =IF(T25="Los Angeles Rams",1,0) -> 0 | U6: =IF(U25="Tampa Bay Buccaneers",1,0) -> 0 | V6: =IF(V25="Dallas Cowboys",1,0) -> 0 | W6: =IF(W25="Denver Broncos",1,0) -> 0 | X6: =IF(X25="Jacksonville Jaguars",1,0) -> 0 | Y6: =IF(Y25="Seattle Seahawks",1,0) -> 0
A7: SJay | B7: PHI | C7: LAC | D7: CHI | E7: LAR | F7: BAL | G7: DEN | H7: IND | I7: PIT | J7: HOU | K7: TB | L7: NYG | M7: BUF | N7: NE | O7: ARI | P7: DET | Q7: KC | R7: BAL | S7: TB | T7: LAR | U7: TB | V7: WAS | W7: DEN | X7: TEN | Y7: SF | Z7: =SUM(B8:Y8) -> 8
B8: =IF(B25="Philadelphia Eagles",1,0) -> 1 | C8: =IF(C25="Los Angeles Chargers",1,0) -> 1 | D8: =IF(D25="Chicago Bears",1,0) -> 0 | E8: =IF(E25="Los Angeles Rams",1,0) -> 1 | F8: =IF(F25="Baltimore Ravens",1,0) -> 0 | G8: =IF(G25="Denver Broncos",1,0) -> 1 | H8: =IF(H25="Indianapolis Colts",1,0) -> 1 | I8: =IF(I25="Pittsburgh Steelers",1,0) -> 1 | J8: =IF(J25="Houston Texans",1,0) -> 0 | K8: =IF(K25="Tampa Bay Buccaneers",1,0) -> 1 | L8: =IF(L25="New York Giants",1,0) -> 0 | M8: =IF(M25="Buffalo Bills",1,0) -> 0 | N8: =IF(N25="New England Patriots",1,0) -> 1 | O8: =IF(O25="Arizona Cardinals",1,0) -> 0 | P8: =IF(P25="Detroit Lions",1,0) -> 0 | Q8: =IF(Q25="Kansas City Chiefs",1,0) -> 0 | R8: =IF(R25="Baltimore Ravens",1,0) -> 0 | S8: =IF(S25="Tampa Bay Buccaneers",1,0) -> 0 | T8: =IF(T25="Los Angeles Rams",1,0) -> 0 | U8: =IF(U25="Tampa Bay Buccaneers",1,0) -> 0 | V8: =IF(V25="Washington Commanders",1,0) -> 0 | W8: =IF(W25="Denver Broncos",1,0) -> 0 | X8: =IF(X25="Tennessee Titans",1,0) -> 0 | Y8: =IF(Y25="San Francisco 49ers",1,0) -> 0
A9: Boots | B9: PHI | C9: LAC | D9: CHI | E9: TEN | F9: BAL | G9: DEN | H9: IND | I9: PIT | J9: HOU | K9: TB | L9: NYG | M9: BUF | N9: NE | O9: ARI | P9: GB | Q9: KC | R9: BAL | S9: TB | T9: LAR | U9: TB | V9: DAL | W9: DEN | X9: TEN | Y9: SF | Z9: =SUM(B10:Y10) -> 8
B10: =IF(B25="Philadelphia Eagles",1,0) -> 1 | C10: =IF(C25="Los Angeles Chargers",1,0) -> 1 | D10: =IF(D25="Chicago Bears",1,0) -> 0 | E10: =IF(E25="Tennessee Titans",1,0) -> 0 | F10: =IF(F25="Baltimore Ravens",1,0) -> 0 | G10: =IF(G25="Denver Broncos",1,0) -> 1 | H10: =IF(H25="Indianapolis Colts",1,0) -> 1 | I10: =IF(I25="Pittsburgh Steelers",1,0) -> 1 | J10: =IF(J25="Houston Texans",1,0) -> 0 | K10: =IF(K25="Tampa Bay Buccaneers",1,0) -> 1 | L10: =IF(L25="New York Giants",1,0) -> 0 | M10: =IF(M25="Buffalo Bills",1,0) -> 0 | N10: =IF(N25="New England Patriots",1,0) -> 1 | O10: =IF(O25="Arizona Cardinals",1,0) -> 0 | P10: =IF(P25="Green Bay Packers",1,0) -> 1 | Q10: =IF(Q25="Kansas City Chiefs",1,0) -> 0 | R10: =IF(R25="Baltimore Ravens",1,0) -> 0 | S10: =IF(S25="Tampa Bay Buccaneers",1,0) -> 0 | T10: =IF(T25="Los Angeles Rams",1,0) -> 0 | U10: =IF(U25="Tampa Bay Buccaneers",1,0) -> 0 | V10: =IF(V25="Dallas Cowboys",1,0) -> 0 | W10: =IF(W25="Denver Broncos",1,0) -> 0 | X10: =IF(X25="Tennessee Titans",1,0) -> 0 | Y10: =IF(Y25="San Francisco 49ers",1,0) -> 0
A11: Colby | B11: PHI | C11: LAC | D11: MIN | E11: LAR | F11: BAL | G11: DEN | H11: LV | I11: PIT | J11: HOU | K11: TB | L11: SF | M11: BUF | N11: NE | O11: ARI | P11: DET | Q11: KC | R11: BAL | S11: TB | T11: LAR | U11: TB | V11: WAS | W11: DEN | X11: JAX | Y11: SF | Z11: =SUM(B12:Y12) -> 9
B12: =IF(B25="Philadelphia Eagles",1,0) -> 1 | C12: =IF(C25="Los Angeles Chargers",1,0) -> 1 | D12: =IF(D25="Minnesota Vikings",1,0) -> 1 | E12: =IF(E25="Los Angeles Rams",1,0) -> 1 | F12: =IF(F25="Baltimore Ravens",1,0) -> 0 | G12: =IF(G25="Denver Broncos",1,0) -> 1 | H12: =IF(H25="Las Vegas Raiders",1,0) -> 0 | I12: =IF(I25="Pittsburgh Steelers",1,0) -> 1 | J12: =IF(J25="Houston Texans",1,0) -> 0 | K12: =IF(K25="Tampa Bay Buccaneers",1,0) -> 1 | L12: =IF(L25="San Francisco 49ers",1,0) -> 1 | M12: =IF(M25="Buffalo Bills",1,0) -> 0 | N12: =IF(N25="New England Patriots",1,0) -> 1 | O12: =IF(O25="Arizona Cardinals",1,0) -> 0 | P12: =IF(P25="Detroit Lions",1,0) -> 0 | Q12: =IF(Q25="Kansas City Chiefs",1,0) -> 0 | R12: =IF(R25="Baltimore Ravens",1,0) -> 0 | S12: =IF(S25="Tampa Bay Buccaneers",1,0) -> 0 | T12: =IF(T25="Los Angeles Rams",1,0) -> 0 | U12: =IF(U25="Tampa Bay Buccaneers",1,0) -> 0 | V12: =IF(V25="Washington Commanders",1,0) -> 0 | W12: =IF(W25="Denver Broncos",1,0) -> 0 | X12: =IF(X25="Jacksonville Jaguars",1,0) -> 0 | Y12: =IF(Y25="San Francisco 49ers",1,0) -> 0
A13: Me | B13: PHI | C13: KC | D13: CHI | E13: LAR | F13: BAL | G13: DEN | H13: LV | I13: PIT | J13: HOU | K13: TB | L13: NYG | M13: BUF | N13: NE | O13: ARI | P13: DET | Q13: KC | R13: BAL | S13: TB | T13: LAR | U13: TB | V13: WAS | W13: DEN | X13: JAX | Y13: SF | Z13: =SUM(B14:Y14) -> 6
B14: =IF(B25="Philadelphia Eagles",1,0) -> 1 | C14: =IF(C25="Kansas City Chiefs",1,0) -> 0 | D14: =IF(D25="Chicago Bears",1,0) -> 0 | E14: =IF(E25="Los Angeles Rams",1,0) -> 1 | F14: =IF(F25="Baltimore Ravens",1,0) -> 0 | G14: =IF(G25="Denver Broncos",1,0) -> 1 | H14: =IF(H25="Las Vegas Raiders",1,0) -> 0 | I14: =IF(I25="Pittsburgh Steelers",1,0) -> 1 | J14: =IF(J25="Houston Texans",1,0) -> 0 | K14: =IF(K25="Tampa Bay Buccaneers",1,0) -> 1 | L14: =IF(L25="New York Giants",1,0) -> 0 | M14: =IF(M25="Buffalo Bills",1,0) -> 0 | N14: =IF(N25="New England Patriots",1,0) -> 1 | O14: =IF(O25="Arizona Cardinals",1,0) -> 0 | P14: =IF(P25="Detroit Lions",1,0) -> 0 | Q14: =IF(Q25="Kansas City Chiefs",1,0) -> 0 | R14: =IF(R25="Baltimore Ravens",1,0) -> 0 | S14: =IF(S25="Tampa Bay Buccaneers",1,0) -> 0 | T14: =IF(T25="Los Angeles Rams",1,0) -> 0 | U14: =IF(U25="Tampa Bay Buccaneers",1,0) -> 0 | V14: =IF(V25="Washington Commanders",1,0) -> 0 | W14: =IF(W25="Denver Broncos",1,0) -> 0 | X14: =IF(X25="Jacksonville Jaguars",1,0) -> 0 | Y14: =IF(Y25="San Francisco 49ers",1,0) -> 0
A15: Shelley | B15: PHI | C15: LAC | D15: MIN | E15: LAR | F15: BAL | G15: DEN | H15: IND | I15: PIT | J15: SEA | K15: NO | L15: SF | M15: BUF | N15: NE | O15: ARI | P15: DET | Q15: DAL | R15: BAL | S15: TB | T15: SEA | U15: TB | V15: DAL | W15: LAC | X15: JAX | Y15: SEA | Z15: =SUM(B16:Y16) -> 11
B16: =IF(B25="Philadelphia Eagles",1,0) -> 1 | C16: =IF(C25="Los Angeles Chargers",1,0) -> 1 | D16: =IF(D25="Minnesota Vikings",1,0) -> 1 | E16: =IF(E25="Los Angeles Rams",1,0) -> 1 | F16: =IF(F25="Baltimore Ravens",1,0) -> 0 | G16: =IF(G25="Denver Broncos",1,0) -> 1 | H16: =IF(H25="Indianapolis Colts",1,0) -> 1 | I16: =IF(I25="Pittsburgh Steelers",1,0) -> 1 | J16: =IF(J25="Seattle Seahawks",1,0) -> 1 | K16: =IF(K25="New Orleans Saints",1,0) -> 0 | L16: =IF(L25="San Francisco 49ers",1,0) -> 1 | M16: =IF(M25="Buffalo Bills",1,0) -> 0 | N16: =IF(N25="New England Patriots",1,0) -> 1 | O16: =IF(O25="Arizona Cardinals",1,0) -> 0 | P16: =IF(P25="Detroit Lions",1,0) -> 0 | Q16: =IF(Q25="Dallas Cowboys",1,0) -> 1 | R16: =IF(R25="Baltimore Ravens",1,0) -> 0 | S16: =IF(S25="Tampa Bay Buccaneers",1,0) -> 0 | T16: =IF(T25="Seattle Seahawks",1,0) -> 0 | U16: =IF(U25="Tampa Bay Buccaneers",1,0) -> 0 | V16: =IF(V25="Dallas Cowboys",1,0) -> 0 | W16: =IF(W25="Los Angeles Chargers",1,0) -> 0 | X16: =IF(X25="Jacksonville Jaguars",1,0) -> 0 | Y16: =IF(Y25="Seattle Seahawks",1,0) -> 0
A17: Brian | B17: PHI | C17: KC | D17: MIN | E17: LAR | F17: DET | G17: DEN | H17: LV | I17: PIT | J17: SEA | K17: TB | L17: NYG | M17: MIA | N17: NE | O17: ARI | P17: DET | Q17: KC | R17: BAL | S17: ATL | T17: LAR | U17: CAR | V17: DAL | W17: DEN | X17: JAX | Y17: SF | Z17: =SUM(B18:Y18) -> 10
B18: =IF(B25="Philadelphia Eagles",1,0) -> 1 | C18: =IF(C25="Kansas City Chiefs",1,0) -> 0 | D18: =IF(D25="Minnesota Vikings",1,0) -> 1 | E18: =IF(E25="Los Angeles Rams",1,0) -> 1 | F18: =IF(F25="Detroit Lions",1,0) -> 1 | G18: =IF(G25="Denver Broncos",1,0) -> 1 | H18: =IF(H25="Las Vegas Raiders",1,0) -> 0 | I18: =IF(I25="Pittsburgh Steelers",1,0) -> 1 | J18: =IF(J25="Seattle Seahawks",1,0) -> 1 | K18: =IF(K25="Tampa Bay Buccaneers",1,0) -> 1 | L18: =IF(L25="New York Giants",1,0) -> 0 | M18: =IF(M25="Miami Dolphins",1,0) -> 1 | N18: =IF(N25="New England Patriots",1,0) -> 1 | O18: =IF(O25="Arizona Cardinals",1,0) -> 0 | P18: =IF(P25="Detroit Lions",1,0) -> 0 | Q18: =IF(Q25="Kansas City Chiefs",1,0) -> 0 | R18: =IF(R25="Baltimore Ravens",1,0) -> 0 | S18: =IF(S25="Atlanta Falcons",1,0) -> 0 | T18: =IF(T25="Los Angeles Rams",1,0) -> 0 | U18: =IF(U25="Carolina Panthers",1,0) -> 0 | V18: =IF(V25="Dallas Cowboys",1,0) -> 0 | W18: =IF(W25="Denver Broncos",1,0) -> 0 | X18: =IF(X25="Jacksonville Jaguars",1,0) -> 0 | Y18: =IF(Y25="San Francisco 49ers",1,0) -> 0
A19: Bloomers | B19: PHI | C19: KC | D19: MIN | E19: TEN | F19: BAL | G19: DEN | H19: LV | I19: PIT | J19: SEA | K19: TB | L19: NYG | M19: BUF | N19: NYJ | O19: JAX | P19: DET | Q19: KC | R19: BAL | S19: TB | T19: LAR | U19: TB | V19: WAS | W19: LAC | X19: JAX | Y19: SEA | Z19: =SUM(B20:Y20) -> 7
B20: =IF(B25="Philadelphia Eagles",1,0) -> 1 | C20: =IF(C25="Kansas City Chiefs",1,0) -> 0 | D20: =IF(D25="Minnesota Vikings",1,0) -> 1 | E20: =IF(E25="Tennessee Titans",1,0) -> 0 | F20: =IF(F25="Baltimore Ravens",1,0) -> 0 | G20: =IF(G25="Denver Broncos",1,0) -> 1 | H20: =IF(H25="Las Vegas Raiders",1,0) -> 0 | I20: =IF(I25="Pittsburgh Steelers",1,0) -> 1 | J20: =IF(J25="Seattle Seahawks",1,0) -> 1 | K20: =IF(K25="Tampa Bay Buccaneers",1,0) -> 1 | L20: =IF(L25="New York Giants",1,0) -> 0 | M20: =IF(M25="Buffalo Bills",1,0) -> 0 | N20: =IF(N25="New York Jets",1,0) -> 0 | O20: =IF(O25="Jacksonville Jaguars",1,0) -> 1 | P20: =IF(P25="Detroit Lions",1,0) -> 0 | Q20: =IF(Q25="Kansas City Chiefs",1,0) -> 0 | R20: =IF(R25="Baltimore Ravens",1,0) -> 0 | S20: =IF(S25="Tampa Bay Buccaneers",1,0) -> 0 | T20: =IF(T25="Los Angeles Rams",1,0) -> 0 | U20: =IF(U25="Tampa Bay Buccaneers",1,0) -> 0 | V20: =IF(V25="Washington Commanders",1,0) -> 0 | W20: =IF(W25="Los Angeles Chargers",1,0) -> 0 | X20: =IF(X25="Jacksonville Jaguars",1,0) -> 0 | Y20: =IF(Y25="Seattle Seahawks",1,0) -> 0
A21: Tom | B21: PHI | C21: KC | D21: CHI | E21: LAR | F21: BAL | G21: DEN | H21: IND | I21: PIT | J21: HOU | K21: TB | L21: SF | M21: BUF | N21: NE | O21: ARI | P21: DET | Q21: KC | R21: BAL | S21: TB | T21: LAR | U21: TB | V21: WAS | W21: DEN | X21: JAX | Y21: SF | Z21: =SUM(B22:Y22) -> 8
B22: =IF(B25="Philadelphia Eagles",1,0) -> 1 | C22: =IF(C25="Kansas City Chiefs",1,0) -> 0 | D22: =IF(D25="Chicago Bears",1,0) -> 0 | E22: =IF(E25="Los Angeles Rams",1,0) -> 1 | F22: =IF(F25="Baltimore Ravens",1,0) -> 0 | G22: =IF(G25="Denver Broncos",1,0) -> 1 | H22: =IF(H25="Indianapolis Colts",1,0) -> 1 | I22: =IF(I25="Pittsburgh Steelers",1,0) -> 1 | J22: =IF(J25="Houston Texans",1,0) -> 0 | K22: =IF(K25="Tampa Bay Buccaneers",1,0) -> 1 | L22: =IF(L25="San Francisco 49ers",1,0) -> 1 | M22: =IF(M25="Buffalo Bills",1,0) -> 0 | N22: =IF(N25="New England Patriots",1,0) -> 1 | O22: =IF(O25="Arizona Cardinals",1,0) -> 0 | P22: =IF(P25="Detroit Lions",1,0) -> 0 | Q22: =IF(Q25="Kansas City Chiefs",1,0) -> 0 | R22: =IF(R25="Baltimore Ravens",1,0) -> 0 | S22: =IF(S25="Tampa Bay Buccaneers",1,0) -> 0 | T22: =IF(T25="Los Angeles Rams",1,0) -> 0 | U22: =IF(U25="Tampa Bay Buccaneers",1,0) -> 0 | V22: =IF(V25="Washington Commanders",1,0) -> 0 | W22: =IF(W25="Denver Broncos",1,0) -> 0 | X22: =IF(X25="Jacksonville Jaguars",1,0) -> 0 | Y22: =IF(Y25="San Francisco 49ers",1,0) -> 0
A23: Karen | B23: PHI | C23: KC | D23: MIN | E23: TEN | F23: BAL | G23: CIN | H23: LV | I23: PIT | J23: SEA | K23: NO | L23: SF | M23: BUF | N23: NE | O23: JAX | P23: GB | Q23: KC | R23: BAL | S23: TB | T23: SEA | U23: CAR | V23: WAS | W23: LAC | X23: TEN | Y23: SF | Z23: =SUM(B24:Y24) -> 8
B24: =IF(B25="Philadelphia Eagles",1,0) -> 1 | C24: =IF(C25="Kansas City Chiefs",1,0) -> 0 | D24: =IF(D25="Minnesota Vikings",1,0) -> 1 | E24: =IF(E25="Tennessee Titans",1,0) -> 0 | F24: =IF(F25="Baltimore Ravens",1,0) -> 0 | G24: =IF(G25="Cincinnati Bengals",1,0) -> 0 | H24: =IF(H25="Las Vegas Raiders",1,0) -> 0 | I24: =IF(I25="Pittsburgh Steelers",1,0) -> 1 | J24: =IF(J25="Seattle Seahawks",1,0) -> 1 | K24: =IF(K25="New Orleans Saints",1,0) -> 0 | L24: =IF(L25="San Francisco 49ers",1,0) -> 1 | M24: =IF(M25="Buffalo Bills",1,0) -> 0 | N24: =IF(N25="New England Patriots",1,0) -> 1 | O24: =IF(O25="Jacksonville Jaguars",1,0) -> 1 | P24: =IF(P25="Green Bay Packers",1,0) -> 1 | Q24: =IF(Q25="Kansas City Chiefs",1,0) -> 0 | R24: =IF(R25="Baltimore Ravens",1,0) -> 0 | S24: =IF(S25="Tampa Bay Buccaneers",1,0) -> 0 | T24: =IF(T25="Seattle Seahawks",1,0) -> 0 | U24: =IF(U25="Carolina Panthers",1,0) -> 0 | V24: =IF(V25="Washington Commanders",1,0) -> 0 | W24: =IF(W25="Los Angeles Chargers",1,0) -> 0 | X24: =IF(X25="Tennessee Titans",1,0) -> 0 | Y24: =IF(Y25="San Francisco 49ers",1,0) -> 0
A25: Winners | B25: Philadelphia Eagles | C25: Los Angeles Chargers | D25: Minnesota Vikings | E25: Los Angeles Rams | F25: Detroit Lions | G25: Denver Broncos | H25: Indianapolis Colts | I25: Pittsburgh Steelers | J25: Seattle Seahawks | K25: Tampa Bay Buccaneers | L25: San Francisco 49ers | M25: Miami Dolphins | N25: New England Patriots | O25: Jacksonville Jaguars | P25: Green Bay Packers | Q25: Dallas Cowboys | R25: Pittsburgh Steelers
A27: NAME | B27: Divisional winners (2 pts each) | L27: Wildcard teams (3 pts each) | T27: Superbowl (3 pts) | X27: Superbowl Champ (4 pts) | AC27: Playoffs Total | AE27: Regular Season Total | AG27: TOTALITY | AJ27: Max Score
B28: AFC | G28: NFC | L28: AFC | P28: NFC | T28: AFC | V28: NFC | AP28: Notes
B29: E | C29: N | D29: S | E29: W | G29: E | H29: N | I29: S | J29: W
A30: Lori Lynn | B30: BUF | C30: PIT | D30: IND | E30: KC | G30: PHI | H30: MIN | I30: TB | J30: LAR | L30: MIA | M30: HOU | N30: DEN | P30: DET | Q30: ATL | R30: SEA | T30: BUF | V30: PHI | X30: BUF | AE30: =Z5 -> 9 | AG30: =SUM(AC30,AE30) -> 9 | AK30: =SUM(#REF!,AG30) -> #REF!
Q31: X
A32: SJay | B32: BUF | C32: PIT | D32: HOU | E32: KC | G32: PHI | H32: CHI | I32: TB | J32: LAR | L32: NE | M32: TEN | N32: DEN | P32: NYG | Q32: MIN | R32: ARI | T32: TEN | V32: CHI | X32: TEN | AC32: =SUM(B33:Z33) -> 0 | AE32: =Z7 -> 8 | AG32: =SUM(AC32,AE32) -> 8 | AK32: =SUM(#REF!,AG32) -> #REF!
M33: X | P33: X | R33: X | T33: X | X33: X
A34: Boots | B34: BUF | C34: BAL | D34: TEN | E34: KC | G34: NYG | H34: CHI | I34: TB | J34: ARI | L34: NE | M34: PIT | N34: DEN | P34: PHI | Q34: MIN | R34: LAR | T34: KC | V34: LAR | X34: LAR | AC34: =SUM(B35:Z35) -> 0 | AE34: =Z9 -> 8 | AG34: =SUM(AC34,AE34) -> 8 | AK34: =SUM(#REF!,AG34) -> #REF!
D35: X | G35: X | J35: X
A36: Colby | B36: BUF | C36: BAL | D36: HOU | E36: DEN | G36: PHI | H36: DET | I36: TB | J36: LAR | L36: KC | M36: CIN | N36: LAC | P36: SEA | Q36: GB | R36: WAS | T36: BAL | V36: PHI | X36: BAL | AC36: =SUM(B37:Z37) -> 0 | AE36: =Z11 -> 9 | AG36: =SUM(AC36,AE36) -> 9 | AK36: =SUM(#REF!,AG36) -> #REF!
R37: X
A38: Me | B38: BUF | C38: BAL | D38: HOU | E38: KC | G38: WAS | H38: GB | I38: TB | J38: LAR | L38: LAC | M38: DEN | N38: PIT | P38: PHI | Q38: DET | R38: ARI | T38: LAC | V38: GB | X38: LAC | AC38: =SUM(B39:Z39) -> 0 | AE38: =Z13 -> 6 | AG38: =SUM(AC38,AE38) -> 6 | AK38: =SUM(#REF!,AG38) -> #REF!
G39: X | R39: X
A40: Shelley | B40: BUF | C40: BAL | D40: HOU | E40: LAC | G40: PHI | H40: DET | I40: ATL | J40: SEA | L40: PIT | M40: KC | N40: DEN | P40: MIN | Q40: LAR | R40: DAL | T40: BUF | V40: SEA | X40: BUF | AC40: =SUM(B41:Z41) -> 0 | AE40: =Z15 -> 11 | AG40: =SUM(AC40,AE40) -> 11 | AK40: =SUM(#REF!,AG40) -> #REF!
I41: X
A42: Brian | B42: NE | C42: PIT | D42: HOU | E42: KC | G42: DAL | H42: MIN | I42: TB | J42: LAR | L42: BAL | M42: BUF | N42: LAC | P42: PHI | Q42: DET | R42: SF | T42: BUF | V42: PHI | X42: BUF | AC42: =SUM(B43:Z43) -> 0 | AE42: =Z17 -> 10 | AG42: =SUM(AC42,AE42) -> 10 | AK42: =SUM(#REF!,AG42) -> #REF!
...

Sheet faves
A1: First | B1: nick | C1: Last | D1: fave
A2: Joe | C2: Battisti | D2: Texans
A3: Lisa | C3: Brelinski | D3: Chiefs | E3: Seahawks | F3: Oregon QBs: Chargers, Broncos, Browns
A4: Carrie | C4: Carleton | D4: Raiduz
A5: Dave | C5: Carleton | D5: 49ers
A6: Theresa | C6: Carleton | D6: 49ers
A7: Tom | C7: Carleton | D7: Raiduz
A8: Roberta | B8: Red Wing | C8: Crew | D8: Chiefs
A9: William | B9: Sweet | C9: Crew | D9: Chiefs
A10: Denise | C10: Deluna | D10: Cowboys
A11: Chrissy | C11: Dunham | E11: "when I win I'll let you know"
A12: Grant | C12: Dunham | D12: Cowboys
A13: Zack | C13: Dunham | D13: Eagles
A14: Forrest | C14: Fowles | D14: Denver
A15: Karen | C15: Hamllik | D15: Seahawks
A16: Tom | C16: Hamllik | D16: Bills
A17: Mike | B17: emjay | C17: Jacoby | D17: Chargers
A18: Sandy | B18: SJay | C18: Jacoby | D18: Broncos
A19: Jesse | C19: Jones | D19: Chiefs
A20: Brian | C20: McCormick | D20: Seahawks
A21: Shelley | C21: McCormick | D21: Seahawks | E21: 49ers
A22: John | C22: Plechinger | D22: Cowboys
A23: Frank | C23: Spengler | D23: 49ers
A24: Norma Jean | B24: Bloomers | C24: Zelinski | D24: Steelers
A28: Lori Lynn | C28: Hartill
A29: Colby | C29: Schmidt

Sheet team names
A1: full team names to be used for winners on rows 25, 74, and 123 on main
A2: Arizona Cardinals
A3: Atlanta Falcons
A4: Baltimore Ravens
A5: Buffalo Bills
A6: Carolina Panthers
A7: Chicago Bears
A8: Cincinnati Bengals
A9: Cleveland Browns
A10: Dallas Cowboys
A11: Denver Broncos
A12: Detroit Lions
... A33: Washington Commanders

Sheet regularseason
A1: Name | D1: SEPT | I1: OCT | N1: NOV | T1: DEC | X1: JAN | Z1: Totals
B2: 4 | C2: 5 | D2: 8 | E2: 14 | F2: 22 | G2: 29 | H2: 5 | I2: 12 | J2: 20 | K2: 26 | L2: 2 | M2: 9 | N2: 13 | O2: 23 | P2: 27 | Q2: 27 | R2: 7 | S2: 11 | T2: 18 | U2: 21 | V2: 25 | W2: tbd | X2: tbd | Y2: tbd
A3: Gm# | B3: 1 | C3: 2 | D3: 3 | E3: 4 | F3: 5 | G3: 6 | H3: 7 | I3: 8 | J3: 9 | K3: 10 | L3: 11 | M3: 12 | N3: 13 | O3: 14 | P3: 15 | Q3: 16 | R3: 17 | S3: 18 | T3: 19 | U3: 20 | V3: 21 | W3: 22 | X3: 23 | Y3: 24
A4: Lori Lynn | B4: PHI | C4: KC | D4: MIN | E4: LAR | F4: BAL | G4: DEN | H4: IND | I4: PIT | J4: HOU | K4: TB | L4: NYG | M4: BUF | N4: NYJ | O4: JAX | P4: DET | Q4: KC | R4: PIT | S4: TB | T4: LAR | U4: TB | V4: DAL | W4: DEN | X4: JAX | Y4: SEA | Z4: =SUM(B5:Y5) -> 2
B5: 1 | C5: 0 | D5: 1
A6: SJay | B6: PHI | C6: LAC | D6: CHI | E6: LAR | F6: BAL | G6: DEN | H6: IND | I6: PIT | J6: HOU | K6: TB | L6: NYG | M6: BUF | N6: NE | O6: ARI | P6: DET | Q6: KC | R6: BAL | S6: TB | T6: LAR | U6: TB | V6: WAS | W6: DEN | X6: TEN | Y6: SF | Z6: =SUM(B7:Y7) -> 2
B7: 1 | C7: 1 | D7: 0
A8: Boots | B8: PHI | C8: LAC | D8: CHI | E8: TEN | F8: BAL | G8: DEN | H8: IND | I8: PIT | J8: HOU | K8: TB | L8: NYG | M8: BUF | N8: NE | O8: ARI | P8: GB | Q8: KC | R8: BAL | S8: TB | T8: LAR | U8: TB | V8: DAL | W8: DEN | X8: TEN | Y8: SF | Z8: =SUM(B9:Y9) -> 2
B9: 1 | C9: 1 | D9: 0
A10: Colby | B10: PHI | C10: LAC | D10: MIN | E10: LAR | F10: BAL | G10: DEN | H10: LV | I10: PIT | J10: HOU | K10: TB | L10: SF | M10: BUF | N10: NE | O10: ARI | P10: DET | Q10: KC | R10: BAL | S10: TB | T10: LAR | U10: TB | V10: WAS | W10: DEN | X10: JAX | Y10: SF | Z10: =SUM(B11:Y11) -> 3
B11: 1 | C11: 1 | D11: 1
A12: Me | B12: PHI | C12: KC | D12: CHI | E12: LAR | F12: BAL | G12: DEN | H12: LV | I12: PIT | J12: HOU | K12: TB | L12: NYG | M12: BUF | N12: NE | O12: ARI | P12: DET | Q12: KC | R12: BAL | S12: TB | T12: LAR | U12: TB | V12: WAS | W12: DEN | X12: JAX | Y12: SF | Z12: =SUM(B13:Y13) -> 1
B13: 1 | C13: 0 | D13: 0
A14: Shelley | B14: PHI | C14: LAC | D14: MIN | E14: LAR | F14: BAL | G14: DEN | H14: IND | I14: PIT | J14: SEA | K14: NO | L14: SF | M14: BUF | N14: NE | O14: ARI | P14: DET | Q14: DAL | R14: BAL | S14: TB | T14: SEA | U14: TB | V14: DAL | W14: LAC | X14: JAX | Y14: SEA | Z14: =SUM(B15:Y15) -> 3
B15: 1 | C15: 1 | D15: 1
A16: Brian | B16: PHI | C16: KC | D16: MIN | E16: LAR | F16: DET | G16: DEN | H16: LV | I16: PIT | J16: SEA | K16: TB | L16: NYG | M16: MIA | N16: NE | O16: ARI | P16: DET | Q16: KC | R16: BAL | S16: ATL | T16: LAR | U16: CAR | V16: DAL | W16: DEN | X16: JAX | Y16: SF | Z16: =SUM(B17:Y17) -> 2
B17: 1 | C17: 0 | D17: 1
A18: Bloomers | B18: PHI | C18: KC | D18: MIN | E18: TEN | F18: BAL | G18: DEN | H18: LV | I18: PIT | J18: SEA | K18: TB | L18: NYG | M18: BUF | N18: NYJ | O18: JAX | P18: DET | Q18: KC | R18: BAL | S18: TB | T18: LAR | U18: TB | V18: WAS | W18: LAC | X18: JAX | Y18: SEA | Z18: =SUM(B19:Y19) -> 2
B19: 1 | C19: 0 | D19: 1
A20: Tom | B20: PHI | C20: KC | D20: CHI | E20: LAR | F20: BAL | G20: DEN | H20: IND | I20: PIT | J20: HOU | K20: TB | L20: SF | M20: BUF | N20: NE | O20: ARI | P20: DET | Q20: KC | R20: BAL | S20: TB | T20: LAR | U20: TB | V20: WAS | W20: DEN | X20: JAX | Y20: SF | Z20: =SUM(B21:Y21) -> 1
B21: 1 | C21: 0 | D21: 0
A22: Karen | B22: PHI | C22: KC | D22: MIN | E22: TEN | F22: BAL | G22: CIN | H22: LV | I22: PIT | J22: SEA | K22: NO | L22: SF | M22: BUF | N22: NE | O22: JAX | P22: GB | Q22: KC | R22: BAL | S22: TB | T22: SEA | U22: CAR | V22: WAS | W22: LAC | X22: TEN | Y22: SF | Z22: =SUM(B23:Y23) -> 2
B23: 1 | C23: 0 | D23: 1
A24: Denise | B24: DAL | C24: KC | D24: MIN | E24: TEN | F24: BAL | G24: CIN | H24: LV | I24: CLE | J24: SEA | K24: NO | L24: SF | M24: BUF | N24: NE | O24: ARI | P24: GB | Q24: KC | R24: BAL | S24: ATL | T24: LAR | U24: CAR | V24: WAS | W24: LAC | X24: JAX | Y24: SF | Z24: =SUM(B25:Y25) -> 1
B25: 0 | C25: 0 | D25: 1
A26: Frank | B26: PHI | C26: KC | D26: MIN | E26: LAR | F26: BAL | G26: DEN | H26: LV | I26: CLE | J26: SEA | K26: TB | L26: SF | M26: MIA | N26: NYJ | O26: ARI | P26: DET | Q26: KC | R26: BAL | S26: TB | T26: SEA | U26: TB | V26: DAL | W26: LAC | X26: TEN | Y26: SF | Z26: =SUM(B27:Y27) -> 2
B27: 1 | C27: 0 | D27: 1
A28: Tom C | B28: PHI | C28: LAC | D28: MIN | E28: TEN | F28: BAL | G28: CIN | H28: LV | I28: PIT | J28: HOU | K28: TB | L28: SF | M28: BUF | N28: NE | O28: ARI | P28: DET | Q28: KC | R28: BAL | S28: TB | T28: LAR | U28: TB | V28: WAS | W28: LAC | X28: TEN | Y28: SF | Z28: =SUM(B29:Y29) -> 3
B29: 1 | C29: 1 | D29: 1
A30: Carrie | B30: PHI | C30: LAC | D30: MIN | E30: LAR | F30: DET | G30: DEN | H30: LV | I30: PIT | J30: SEA | K30: TB | L30: SF | M30: BUF | N30: NE | O30: JAX | P30: DET | Q30: DAL | R30: BAL | S30: TB | T30: SEA | U30: TB | V30: WAS | W30: LAC | X30: JAX | Y30: SF | Z30: =SUM(B31:Y31) -> 3
B31: 1 | C31: 1 | D31: 1
A32: Al | B32: PHI | C32: KC | D32: CHI | E32: LAR | F32: BAL | G32: DEN | H32: IND | I32: PIT | J32: HOU | K32: TB | L32: SF | M32: BUF | N32: NE | O32: ARI | P32: DET | Q32: KC | R32: BAL | S32: TB | T32: LAR | U32: TB | V32: WAS | W32: DEN | X32: JAX | Y32: SF | Z32: =SUM(B33:Y33) -> 1
B33: 1 | C33: 0 | D33: 0
A34: Kaleb | B34: PHI | C34: LAC | D34: CHI | E34: LAR | F34: BAL | G34: DEN | H34: LV | I34: PIT | J34: HOU | K34: TB | L34: NYG | M34: BUF | N34: NE | O34: ARI | P34: GB | Q34: DAL | R34: BAL | S34: TB | T34: LAR | U34: TB | V34: WAS | W34: DEN | X34: JAX | Y34: SF | Z34: =SUM(B35:Y35) -> 2
B35: 1 | C35: 1 | D35: 0
A36: Winners | B36: PHI | C36: LAC | D36: MIN
A37: Name | D37: SEPT | I37: OCT | N37: NOV | T37: DEC | X37: JAN | Z37: Totals
B38: 4 | C38: 5 | D38: 8 | E38: 14 | F38: 22 | G38: 29 | H38: 5 | I38: 12 | J38: 20 | K38: 26 | L38: 2 | M38: 9 | N38: 13 | O38: 23 | P38: 27 | Q38: 27 | R38: 7 | S38: 11 | T38: 18 | U38: 21 | V38: 25 | W38: tbd | X38: tbd | Y38: tbd
A39: Gm# | B39: 1 | C39: 2 | D39: 3 | E39: 4 | F39: 5 | G39: 6 | H39: 7 | I39: 8 | J39: 9 | K39: 10 | L39: 11 | M39: 12 | N39: 13 | O39: 14 | P39: 15 | Q39: 16 | R39: 17 | S39: 18 | T39: 19 | U39: 20 | V39: 21 | W39: 22 | X39: 23 | Y39: 24
A40: Robyn | B40: PHI | C40: KC | D40: MIN | E40: LAR | F40: BAL | G40: CIN | H40: IND | I40: PIT | J40: HOU | K40: TB | L40: SF | M40: BUF | N40: NYJ | O40: ARI | P40: DET | Q40: KC | R40: BAL | S40: TB | T40: LAR | U40: TB | V40: WAS | W40: DEN | X40: JAX | Y40: SF | Z40: =SUM(B41:Y41) -> 2
...

Sheet postseason
A1: NAME | B1: Divisional winners (2 pts each) | L1: Wildcard teams (3 pts each) | T1: SBteams3 | X1: Champ4 | AB1: Playoffs Total | AD1: Season Total | AF1: TOTALITY
B2: AFC | G2: NFC | L2: AFC | P2: NFC | T2: AFC | V2: NFC
B3: E | C3: N | D3: S | E3: W | G3: E | H3: N | I3: S | J3: W
A4: Lori Lynn | B4: BUF | C4: PIT | D4: IND | E4: KC | G4: PHI | H4: MIN | I4: TB | J4: LAR | L4: MIA | M4: HOU | N4: DEN | P4: DET | Q4: ATL | R4: SEA | T4: BUF | V4: PHI | X4: BUF
A6: SJay | B6: BUF | C6: PIT | D6: HOU | E6: KC | G6: PHI | H6: CHI | I6: TB | J6: LAR | L6: NE | M6: TEN | N6: DEN | P6: NYG | Q6: MIN | R6: ARI | T6: TEN | V6: CHI | X6: TEN
A8: Boots | B8: BUF | C8: BAL | D8: TEN | E8: KC | G8: NYG | H8: CHI | I8: TB | J8: ARI | L8: NE | M8: PIT | N8: DEN | P8: PHI | Q8: MIN | R8: LAR | T8: KC | V8: LAR | X8: LAR
A10: Colby | B10: BUF | C10: BAL | D10: HOU | E10: DEN | G10: PHI | H10: DET | I10: TB | J10: LAR | L10: KC | M10: CIN | N10: LAC | P10: SEA | Q10: GB | R10: WAS | T10: BAL | V10: PHI | X10: BAL
A12: Me | B12: BUF | C12: BAL | D12: HOU | E12: KC | G12: WAS | H12: GB | I12: TB | J12: LAR | L12: LAC | M12: DEN | N12: PIT | P12: PHI | Q12: DET | R12: ARI | T12: LAC | V12: GB | X12: LAC
A14: Shelley | B14: BUF | C14: BAL | D14: HOU | E14: LAC | G14: PHI | H14: DET | I14: ATL | J14: SEA | L14: PIT | M14: KC | N14: DEN | P14: MIN | Q14: LAR | R14: DAL | T14: BUF | V14: SEA | X14: BUF
A16: Brian | B16: NE | C16: PIT | D16: HOU | E16: KC | G16: DAL | H16: MIN | I16: TB | J16: LAR | L16: BAL | M16: BUF | N16: LAC | P16: PHI | Q16: DET | R16: SF | T16: BUF | V16: PHI | X16: BUF
A18: Bloomers | B18: BUF | C18: BAL | D18: TEN | E18: KC | G18: PHI | H18: DET | I18: TB | J18: LAR | L18: LAC | M18: PIT | N18: CIN | P18: MIN | Q18: GB | R18: WAS | T18: LAC | V18: PHI | X18: LAC
A20: Tom | B20: BUF | C20: BAL | D20: HOU | E20: KC | G20: PHI | H20: DET | I20: TB | J20: LAR | L20: BUF | M20: BAL | N20: KC | P20: PHI | Q20: DET | R20: LAR | T20: KC | V20: PHI | X20: KC
A22: Karen | B22: BUF | C22: BAL | D22: TEN | E22: KC | G22: PHI | H22: MIN | I22: ATL | J22: SEA | L22: CIN | M22: IND | N22: LV | P22: WAS | Q22: MIN | R22: SF | T22: BUF | V22: PHI | X22: BUF
A24: Denise | B24: BUF | C24: BAL | D24: TEN | E24: LV | G24: PHI | H24: DET | I24: TB | J24: SF | L24: DEN | M24: CIN | N24: LAC | P24: DET | Q24: LAR | R24: DAL | T24: KC | V24: PHI | X24: KC
A26: Frank | B26: MIA | C26: BAL | D26: HOU | E26: KC | G26: PHI | H26: GB | I26: TB | J26: SF | L26: BUF | M26: LAC | N26: PIT | P26: DET | Q26: LAR | R26: SEA | T26: SF | V26: KC | X26: SF
... A32: AL | B32: BUF | C32: BAL | D32: HOU | E32: KC | G32: PHI | H32: DET | I32: TB | J32: SF | L32: PIT | M32: DEN | N32: LAC | P32: WAS | Q32: GB | R32: LAR | T32: BAL | V32: PHI | X32: BAL
A35: NAME | B35: Divisional winners (2 pts each) | L35: Wildcard teams (3 pts each) | T35: SBteams3 | X35: Champ4 | AB35: Playoffs Total | AD35: Season Total | AF35: TOTALITY
B36: AFC | G36: NFC | L36: AFC | P36: NFC | T36: AFC | V36: NFC
B37: E | C37: N | D37: S | E37: W | G37: E | H37: N | I37: S | J37: W
A38: Kaleb | B38: BUF | C38: BAL | D38: HOU | E38: DEN | G38: PHI | H38: GB | I38: TB | J38: LAR | L38: CIN | M38: PIT | N38: KC | P38: WAS | Q38: DET | R38: SF | T38: BUF | V38: LAR | X38: BUF
A40: Robyn | B40: BUF | C40: BAL | D40: HOU | E40: KC | G40: PHI | H40: DET | I40: TB | J40: SF | L40: CIN | M40: JAX | N40: DEN | P40: ATL | Q40: LAR | R40: GB | T40: SF | V40: KC | X40: SF
A42: Kyle | B42: BUF | C42: BAL | D42: HOU | E42: KC | G42: PHI | H42: GB | I42: TB | J42: SEA | L42: CIN | M42: LAC | N42: NE | P42: WAS | Q42: DET | R42: LAR | T42: BUF | V42: PHI | X42: BUF
A44: Dave C | B44: BUF | C44: BAL | D44: HOU | E44: KC | G44: PHI | H44: DET | I44: TB | J44: SF | L44: CIN | M44: LAC | N44: MIA | P44: GB | Q44: LAR | R44: DAL | T44: SF | V44: BAL | X44: SF
A46: Theresa | B46: BUF | C46: CIN | D46: HOU | E46: LV | G46: PHI | H46: GB | I46: TB | J46: SF | L46: BAL | M46: LAR | N46: KC | P46: SEA | Q46: DET | R46: MIN | T46: SF | V46: BUF | X46: SF
A48: Lisa B | B48: BUF | C48: BAL | D48: HOU | E48: KC | G48: PHI | H48: DET | I48: NO | J48: LAR | L48: LAC | M48: PIT | N48: DEN | P48: TB | Q48: SF | R48: SEA | T48: KC | V48: DET | X48: BUF
A50: John | B50: BUF | C50: BAL | D50: HOU | E50: LAC | G50: PHI | H50: GB | I50: ATL | J50: SF | L50: KC | M50: PIT | N50: DEN | P50: DET | Q50: TB | R50: LAR | T50: BAL | V50: PHI | X50: BAL
A52: Forrest | B52: BUF | C52: BAL | D52: HOU | E52: DEN | G52: PHI | H52: GB | I52: TB | J52: LAR | L52: KC | M52: LAC | N52: CIN | P52: DET | Q52: SF | R52: WAS | T52: BUF | V52: DET | X52: BUF
A54: Jessse | B54: BUF | C54: BAL | D54: HOU | E54: KC | G54: WAS | H54: DET | I54: ATL | J54: LAR | L54: CIN | M54: DEN | N54: MIA | P54: PHI | Q54: GB | R54: SF | T54: BAL | V54: DET | X54: BAL
A56: Roberta | B56: MIA | C56: BAL | D56: HOU | E56: KC | G56: PHI | H56: MIN | I56: TB | J56: SEA | L56: BUF | M56: TEN | N56: DEN | P56: DAL | Q56: LAR | R56: GB | T56: KC | V56: PHI | X56: KC
A58: William | B58: BUF | C58: BAL | D58: HOU | E58: KC | G58: PHI | H58: DET | I58: TB | J58: SEA | L58: MIA | M58: DEN | N58: IND | P58: MIN | Q58: LAR | R58: DAL | T58: KC | V58: PHI | X58: KC
A60: Joe | B60: BUF | C60: CIN | D60: HOU | E60: KC | G60: PHI | H60: DET | I60: ATL | J60: SEA | L60: PIT | M60: TEN | N60: LAC | P60: WAS | Q60: GB | R60: LAR | T60: BUF | V60: PHI | X60: BUF
... A66: Chrissy | B66: BUF | C66: CIN | D66: HOU | E66: KC | G66: PHI | H66: GB | I66: TB | J66: SEA | L66: LAC | M66: PIT | N66: IND | P66: WAS | Q66: LAR | R66: GB | T66: BUF | V66: PHI | X66: BUF

Sheet Week-by-Week Games Table (2)
A1: Column1 | B1: Column2 | C1: Column3 | D1: Column4 | E1: Column5 | F1: Column6 | G1: Column7 | H1: Column8 | I1: Column9 | J1: Column10 | K1: Column11 | L1: Column12 | M1: Column13 | N1: Column14 | O1: Column15 | P1: Column16 | Q1: NFL_Teams | R1: Abbreviation
A2: Week | B2: Day | C2: Date | D2: Time | E2: Winner/tie | G2: Loser/tie | I2: PtsW | J2: PtsL | K2: YdsW | L2: TOW | M2: YdsL | N2: TOL | O2: =IF(I2>J2, E2, IF(I2<J2, G2, "Tie")) -> Winner/tie | Q2: NFL_Teams | R2: ABB
A3: 1 | B3: Thu | C3: 2024-09-05 | D3: 8:20PM | E3: Kansas City Chiefs | G3: Baltimore Ravens | H3: boxscore | I3: 27 | J3: 20 | K3: 353 | L3: 1 | M3: 452 | N3: 1 | O3: =IF(I3>J3, E3, IF(I3<J3, G3, "Tie")) -> Kansas City Chiefs | P3: 1 | Q3: Arizona Cardinals | R3: ARI
A4: 1 | B4: Fri | C4: 2024-09-06 | D4: 8:15PM | E4: Philadelphia Eagles | G4: Green Bay Packers | H4: boxscore | I4: 34 | J4: 29 | K4: 410 | L4: 3 | M4: 414 | N4: 1 | O4: =IF(I4>J4, E4, IF(I4<J4, G4, "Tie")) -> Philadelphia Eagles | P4: 2 | Q4: Atlanta Falcons | R4: ATL
A5: 1 | B5: Sun | C5: 2024-09-08 | D5: 1:00PM | E5: Pittsburgh Steelers | F5: @ | G5: Atlanta Falcons | H5: boxscore | I5: 18 | J5: 10 | K5: 270 | L5: 0 | M5: 226 | N5: 3 | O5: =IF(I5>J5, E5, IF(I5<J5, G5, "Tie")) -> Pittsburgh Steelers | Q5: Baltimore Ravens | R5: BAL
A6: 1 | B6: Sun | C6: 2024-09-08 | D6: 1:00PM | E6: Buffalo Bills | G6: Arizona Cardinals | H6: boxscore | I6: 34 | J6: 28 | K6: 352 | L6: 1 | M6: 270 | N6: 1 | O6: =IF(I6>J6, E6, IF(I6<J6, G6, "Tie")) -> Buffalo Bills | Q6: Buffalo Bills | R6: BUF
A7: 1 | B7: Sun | C7: 2024-09-08 | D7: 1:00PM | E7: New Orleans Saints | G7: Carolina Panthers | H7: boxscore | I7: 47 | J7: 10 | K7: 379 | L7: 1 | M7: 193 | N7: 3 | O7: =IF(I7>J7, E7, IF(I7<J7, G7, "Tie")) -> New Orleans Saints | Q7: Carolina Panthers | R7: CAR
A8: 1 | B8: Sun | C8: 2024-09-08 | D8: 1:00PM | E8: Chicago Bears | G8: Tennessee Titans | H8: boxscore | I8: 24 | J8: 17 | K8: 148 | L8: 1 | M8: 244 | N8: 3 | O8: =IF(I8>J8, E8, IF(I8<J8, G8, "Tie")) -> Chicago Bears | Q8: Chicago Bears | R8: CHX
A9: 1 | B9: Sun | C9: 2024-09-08 | D9: 1:00PM | E9: New England Patriots | F9: @ | G9: Cincinnati Bengals | H9: boxscore | I9: 16 | J9: 10 | K9: 290 | L9: 0 | M9: 224 | N9: 2 | O9: =IF(I9>J9, E9, IF(I9<J9, G9, "Tie")) -> New England Patriots | Q9: Cincinnati Bengals | R9: CIN
A10: 1 | B10: Sun | C10: 2024-09-08 | D10: 1:00PM | E10: Houston Texans | F10: @ | G10: Indianapolis Colts | H10: boxscore | I10: 29 | J10: 27 | K10: 417 | L10: 0 | M10: 303 | N10: 1 | O10: =IF(I10>J10, E10, IF(I10<J10, G10, "Tie")) -> Houston Texans | Q10: Cleveland Browns | R10: CLE
A11: 1 | B11: Sun | C11: 2024-09-08 | D11: 1:00PM | E11: Miami Dolphins | G11: Jacksonville Jaguars | H11: boxscore | I11: 20 | J11: 17 | K11: 400 | L11: 0 | M11: 267 | N11: 1 | O11: =IF(I11>J11, E11, IF(I11<J11, G11, "Tie")) -> Miami Dolphins | Q11: Dallas Cowboys | R11: DAL
A12: 1 | B12: Sun | C12: 2024-09-08 | D12: 1:00PM | E12: Minnesota Vikings | F12: @ | G12: New York Giants | H12: boxscore | I12: 28 | J12: 6 | K12: 312 | L12: 2 | M12: 240 | N12: 2 | O12: =IF(I12>J12, E12, IF(I12<J12, G12, "Tie")) -> New York Giants | Q12: Denver Broncos | R12: DEN
A13: 1 | B13: Sun | C13: 2024-09-08 | D13: 4:05PM | E13: Seattle Seahawks | G13: Denver Broncos | H13: boxscore | I13: 26 | J13: 20 | K13: 304 | L13: 2 | M13: 231 | N13: 3 | O13: =IF(I13>J13, E13, IF(I13<J13, G13, "Tie")) -> Seattle Seahawks | Q13: Detroit Lions | R13: DEX
A14: 1 | B14: Sun | C14: 2024-09-08 | D14: 4:05PM | E14: Los Angeles Chargers | G14: Las Vegas Raiders | H14: boxscore | I14: 22 | J14: 10 | K14: 316 | L14: 0 | M14: 296 | N14: 3 | O14: =IF(I14>J14, E14, IF(I14<J14, G14, "Tie")) -> Los Angeles Chargers | Q14: Green Bay Packers | R14: GB
A15: 1 | B15: Sun | C15: 2024-09-08 | D15: 4:25PM | E15: Dallas Cowboys | F15: @ | G15: Cleveland Browns | H15: boxscore | I15: 33 | J15: 17 | K15: 265 | L15: 0 | M15: 230 | N15: 2 | O15: =IF(I15>J15, E15, IF(I15<J15, G15, "Tie")) -> Dallas Cowboys | Q15: Houston Texans | R15: HOU
A16: 1 | B16: Sun | C16: 2024-09-08 | D16: 4:25PM | E16: Tampa Bay Buccaneers | G16: Washington Commanders | H16: boxscore | I16: 37 | J16: 20 | K16: 392 | L16: 0 | M16: 299 | N16: 0 | O16: =IF(I16>J16, E16, IF(I16<J16, G16, "Tie")) -> Tampa Bay Buccaneers | Q16: Indianapolis Colts | R16: IND
A17: 1 | B17: Sun | C17: 2024-09-08 | D17: 8:20PM | E17: Detroit Lions | G17: Los Angeles Rams | H17: boxscore | I17: 26 | J17: 20 | K17: 363 | L17: 1 | M17: 387 | N17: 1 | O17: =IF(I17>J17, E17, IF(I17<J17, G17, "Tie")) -> Detroit Lions | Q17: Jacksonville Jaguars | R17: JAX
A18: 1 | B18: Mon | C18: 2024-09-09 | D18: 8:15PM | E18: San Francisco 49ers | G18: New York Jets | H18: boxscore | I18: 32 | J18: 19 | K18: 401 | L18: 0 | M18: 266 | N18: 2 | O18: =IF(I18>J18, E18, IF(I18<J18, G18, "Tie")) -> San Francisco 49ers | P18: 3 | Q18: Kansas City Chiefs | R18: KC
A19: Week | B19: Day | C19: Date | D19: Time | E19: Winner/tie | G19: Loser/tie | I19: PtsW | J19: PtsL | K19: YdsW | L19: TOW | M19: YdsL | N19: TOL | O19: =IF(I19>J19, E19, IF(I19<J19, G19, "Tie")) -> Winner/tie | Q19: Las Vegas Raiders | R19: LV
A20: 2 | B20: Thu | C20: 2024-09-12 | D20: 8:15PM | E20: Buffalo Bills | F20: @ | G20: Miami Dolphins | H20: boxscore | I20: 31 | J20: 10 | K20: 247 | L20: 0 | M20: 351 | N20: 3 | O20: =IF(I20>J20, E20, IF(I20<J20, G20, "Tie")) -> Buffalo Bills | P20: 4 | Q20: Los Angeles Chargers | R20: LAC
A21: 2 | B21: Sun | C21: 2024-09-15 | D21: 1:00PM | E21: Los Angeles Chargers | F21: @ | G21: Carolina Panthers | H21: boxscore | I21: 26 | J21: 3 | K21: 349 | L21: 2 | M21: 159 | N21: 1 | O21: =IF(I21>J21, E21, IF(I21<J21, G21, "Tie")) -> Carolina Panthers | Q21: Los Angeles Rams | R21: LAR
A22: 2 | B22: Sun | C22: 2024-09-15 | D22: 1:00PM | E22: Cleveland Browns | F22: @ | G22: Jacksonville Jaguars | H22: boxscore | I22: 18 | J22: 13 | K22: 297 | L22: 0 | M22: 323 | N22: 0 | O22: =IF(I22>J22, E22, IF(I22<J22, G22, "Tie")) -> Cleveland Browns | Q22: Miami Dolphins | R22: MIA
A23: 2 | B23: Sun | C23: 2024-09-15 | D23: 1:00PM | E23: Green Bay Packers | G23: Indianapolis Colts | H23: boxscore | I23: 16 | J23: 10 | K23: 383 | L23: 1 | M23: 338 | N23: 3 | O23: =IF(I23>J23, E23, IF(I23<J23, G23, "Tie")) -> Green Bay Packers | Q23: Minnesota Vikings | R23: MIN
A24: 2 | B24: Sun | C24: 2024-09-15 | D24: 1:00PM | E24: New Orleans Saints | F24: @ | G24: Dallas Cowboys | H24: boxscore | I24: 44 | J24: 19 | K24: 432 | L24: 1 | M24: 353 | N24: 2 | O24: =IF(I24>J24, E24, IF(I24<J24, G24, "Tie")) -> New Orleans Saints | Q24: New England Patriots | R24: NE
A25: 2 | B25: Sun | C25: 2024-09-15 | D25: 1:00PM | E25: Tampa Bay Buccaneers | F25: @ | G25: Detroit Lions | H25: boxscore | I25: 20 | J25: 16 | K25: 216 | L25: 1 | M25: 463 | N25: 2 | O25: =IF(I25>J25, E25, IF(I25<J25, G25, "Tie")) -> Tampa Bay Buccaneers | Q25: New Orleans Saints | R25: NO
A26: 2 | B26: Sun | C26: 2024-09-15 | D26: 1:00PM | E26: Minnesota Vikings | G26: San Francisco 49ers | H26: boxscore | I26: 23 | J26: 17 | K26: 403 | L26: 2 | M26: 396 | N26: 2 | O26: =IF(I26>J26, E26, IF(I26<J26, G26, "Tie")) -> Minnesota Vikings | Q26: New York Giants | R26: NYG
A27: 2 | B27: Sun | C27: 2024-09-15 | D27: 1:00PM | E27: Seattle Seahawks | F27: @ | G27: New England Patriots | H27: boxscore | I27: 23 | J27: 20 | K27: 358 | L27: 0 | M27: 310 | N27: 0 | O27: =IF(I27>J27, E27, IF(I27<J27, G27, "Tie")) -> Seattle Seahawks | Q27: New York Jets | R27: NYJ
A28: 2 | B28: Sun | C28: 2024-09-15 | D28: 1:00PM | E28: Washington Commanders | G28: New York Giants | H28: boxscore | I28: 21 | J28: 18 | K28: 425 | L28: 0 | M28: 304 | N28: 1 | O28: =IF(I28>J28, E28, IF(I28<J28, G28, "Tie")) -> Washington Commanders | Q28: Philadelphia Eagles | R28: PHI
A29: 2 | B29: Sun | C29: 2024-09-15 | D29: 1:00PM | E29: New York Jets | F29: @ | G29: Tennessee Titans | H29: boxscore | I29: 24 | J29: 17 | K29: 265 | L29: 0 | M29: 300 | N29: 2 | O29: =IF(I29>J29, E29, IF(I29<J29, G29, "Tie")) -> New York Jets | Q29: Pittsburgh Steelers | R29: PIT
A30: 2 | B30: Sun | C30: 2024-09-15 | D30: 1:00PM | E30: Las Vegas Raiders | F30: @ | G30: Baltimore Ravens | H30: boxscore | I30: 26 | J30: 23 | K30: 260 | L30: 1 | M30: 383 | N30: 1 | O30: =IF(I30>J30, E30, IF(I30<J30, G30, "Tie")) -> Las Vegas Raiders | Q30: San Francisco 49ers | R30: SF
A31: 2 | B31: Sun | C31: 2024-09-15 | D31: 4:05PM | E31: Arizona Cardinals | G31: Los Angeles Rams | H31: boxscore | I31: 41 | J31: 10 | K31: 489 | L31: 1 | M31: 245 | N31: 1 | O31: =IF(I31>J31, E31, IF(I31<J31, G31, "Tie")) -> Arizona Cardinals | Q31: Seattle Seahawks | R31: SEA
A32: 2 | B32: Sun | C32: 2024-09-15 | D32: 4:25PM | E32: Kansas City Chiefs | G32: Cincinnati Bengals | H32: boxscore | I32: 26 | J32: 25 | K32: 286 | L32: 3 | M32: 320 | N32: 1 | O32: =IF(I32>J32, E32, IF(I32<J32, G32, "Tie")) -> Kansas City Chiefs | Q32: Tampa Bay Buccaneers | R32: TB
A33: 2 | B33: Sun | C33: 2024-09-15 | D33: 4:25PM | E33: Pittsburgh Steelers | F33: @ | G33: Denver Broncos | H33: boxscore | I33: 13 | J33: 6 | K33: 251 | L33: 0 | M33: 295 | N33: 2 | O33: =IF(I33>J33, E33, IF(I33<J33, G33, "Tie")) -> Denver Broncos | Q33: Tennessee Titans | R33: TEN
A34: 2 | B34: Sun | C34: 2024-09-15 | D34: 8:20PM | E34: Houston Texans | G34: Chicago Bears | H34: boxscore | I34: 19 | J34: 13 | K34: 310 | L34: 1 | M34: 205 | N34: 2 | O34: =IF(I34>J34, E34, IF(I34<J34, G34, "Tie")) -> Houston Texans | Q34: Washington Commanders | R34: WAS
A35: 2 | B35: Mon | C35: 2024-09-16 | D35: 8:15PM | E35: Atlanta Falcons | F35: @ | G35: Philadelphia Eagles | H35: boxscore | I35: 22 | J35: 21 | K35: 385 | L35: 0 | M35: 365 | N35: 1 | O35: =IF(I35>J35, E35, IF(I35<J35, G35, "Tie")) -> Atlanta Falcons | P35: 5
A36: Week | B36: Day | C36: Date | D36: Time | E36: Winner/tie | G36: Loser/tie | I36: PtsW | J36: PtsL | K36: YdsW | L36: TOW | M36: YdsL | N36: TOL | O36: =IF(I36>J36, E36, IF(I36<J36, G36, "Tie")) -> Winner/tie
A37: 3 | B37: Thu | C37: 2024-09-19 | D37: 8:15PM | E37: New York Jets | G37: New England Patriots | H37: boxscore | I37: 24 | J37: 3 | K37: 400 | L37: 0 | M37: 139 | N37: 1 | O37: New York Jets | P37: 6
A38: 3 | B38: Sun | C38: 2024-09-22 | D38: 1:00PM | E38: Indianapolis Colts | G38: Chicago Bears | H38: boxscore | I38: 21 | J38: 16 | K38: 306 | L38: 2 | M38: 395 | N38: 3 | O38: =IF(I38>J38, E38, IF(I38<J38, G38, "Tie")) -> Indianapolis Colts
A39: 3 | B39: Sun | C39: 2024-09-22 | D39: 1:00PM | E39: New York Giants | F39: @ | G39: Cleveland Browns | H39: boxscore | I39: 21 | J39: 15 | K39: 340 | L39: 2 | M39: 217 | N39: 2 | O39: =IF(I39>J39, E39, IF(I39<J39, G39, "Tie")) -> New York Giants
A40: 3 | B40: Sun | C40: 2024-09-22 | D40: 1:00PM | E40: Denver Broncos | F40: @ | G40: Tampa Bay Buccaneers | H40: boxscore | I40: 26 | J40: 7 | K40: 352 | L40: 1 | M40: 223 | N40: 2 | O40: =IF(I40>J40, E40, IF(I40<J40, G40, "Tie")) -> Tampa Bay Buccaneers
...
