Workbook

Sheet standings
A1: POS | B1: Participant | C1: Score | E1: POS | F1: Participant | G1: Score | H1: +/- | I1: tpp
A2: 13 | B2: Lori Lynn | C2: =picks!AI31 -> 20 | E2: {=_xlfn._xlws.SORT(A2:C31,3,-1)} -> 1 | F2: Brian | G2: 28 | H2: +2 | I2: 28 | J2: DONE | K2: BUF OVER PHI
A3: 27 | B3: SJay | C3: =picks!AI33 -> 15 | E3: 2 | F3: Carrie | G3: 27 | H3: -1 | I3: 27 | J3: DONE | K3: BILLS ATW DETROIT OUT
A4: 27 | B4: Bootsie | C4: =picks!AI35 -> 15 | E4: 3 | F4: Red Wing | G4: 26 | H4: +6 | I4: 26 | J4: DONE | K4: KC OVER PHI
A5: 10 | B5: Colby | C5: =picks!AI37 -> 21 | E5: 3 | F5: Grant | G5: 26 | H5: +4 | I5: 26 | J5: DONE | K5: BAL OVER PHI
A6: 29 | B6: Emjay | C6: =picks!AI39 -> 11 | E6: 5 | F6: Joe | G6: 25 | H6: +11 | I6: 25 | J6: DONE | K6: BUF OVER PHI | L6: 23rd to 16th to 5th
A7: 9 | B7: Shelley | C7: =picks!AI41 -> 22 | E7: 6 | F7: Chrissy | G7: 24 | H7: +18 | I7: 24 | J7: DONE | K7: BUF OVER PHI | L7: up from 24th
A8: 1 | B8: Brian | C8: =picks!AI43 -> 28 | E8: 7 | F8: Kyle | G8: 23 | H8: even | I8: 23 | J8: DONE | K8: BUF OVER PHI
A9: 22 | B9: Bloomers | C9: =picks!AI45 -> 17 | E9: 7 | F9: Dave C | G9: 23 | H9: +2 | I9: 23 | J9: DONE | K9: SF OVER BAL
A10: 19 | B10: Tom H | C10: =picks!AI47 -> 18 | E10: 9 | F10: Shelley | G10: 22 | H10: -6 | I10: 25 | K10: BUF OVER SEA
A11: 22 | B11: Karen | C11: =picks!AI49 -> 17 | E11: 10 | F11: Colby | G11: 21 | H11: -1 | I11: 21 | J11: DONE | K11: BAL OVER PHI
A12: 25 | B12: Denise | C12: =picks!AI85 -> 16 | E12: 10 | F12: Frank | G12: 21 | H12: +6 | I12: 21 | J12: DONE | K12: SF OVER KC
A13: 10 | B13: Frank | C13: =picks!AI87 -> 21 | E13: 10 | F13: Al | G13: 21 | H13: +6 | I13: 21 | J13: DONE | K13: BAL OVER PHI
A14: 19 | B14: Tom C | C14: =picks!AI89 -> 18 | E14: 13 | F14: Lori Lynn | G14: 20 | H14: -4 | I14: 20 | J14: DONE | K14: BUF OVER PHI
A15: 2 | B15: Carrie | C15: =picks!AI91 -> 27 | E15: 13 | F15: Forrest | G15: 20 | H15: +3 | I15: 20 | J15: DONE | K15: BUF OVER DET
A16: 10 | B16: Al | C16: =picks!AI93 -> 21 | E16: 13 | F16: William | G16: 20 | H16: -10 | I16: 20 | J16: DONE | K16: KC OVER PHI
A17: 19 | B17: Kaleb | C17: =picks!AI95 -> 18 | E17: 13 | F17: Zack | G17: 20 | H17: -10 | I17: 20 | J17: DONE | K17: PHI OVER BAL | L17: 12th to 3rd to 13th
A18: 22 | B18: Robyn | C18: =picks!AI97 -> 17 | E18: 17 | F18: Lisa | G18: 19 | H18: -8 | I18: 19 | J18: DONE | K18: BUF OVER KC/DET
A19: 7 | B19: Kyle | C19: =picks!AI99 -> 23 | E19: 17 | F19: John | G19: 19 | H19: -15 | I19: 19 | J19: DONE | K19: BAL OVER PHI
A20: 7 | B20: Dave C | C20: =picks!AI101 -> 23 | E20: 19 | F20: Tom H | G20: 18 | H20: -3 | I20: 18 | J20: DONE | K20: KC OVER PHI
A21: 29 | B21: Theresa | C21: =picks!AI103 -> 11 | E21: 19 | F21: Tom C | G21: 18 | H21: +5 | I21: 18 | J21: DONE | K21: BUF OVER PHI
A22: 17 | B22: Lisa | C22: =picks!AI136 -> 19 | E22: 19 | F22: Kaleb | G22: 18 | H22: -10 | I22: 21 | K22: BUF OVER LAR
A23: 17 | B23: John | C23: =picks!AI138 -> 19 | E23: 22 | F23: Bloomers | G23: 17 | H23: -2 | I23: 17 | J23: DONE | K23: LAC OVER PHI
A24: 13 | B24: Forrest | C24: =picks!AI140 -> 20 | E24: 22 | F24: Karen | G24: 17 | H24: -6 | I24: 17 | J24: DONE | K24: BUF OVER PHI | L24: 29th to 16th to 22nd
A25: 25 | B25: Jesse | C25: =picks!AI142 -> 16 | E25: 22 | F25: Robyn | G25: 17 | H25: +2 | I25: 17 | J25: DONE | K25: SF OVER KC
A26: 3 | B26: Red Wing | C26: =picks!AI144 -> 26 | E26: 25 | F26: Denise | G26: 16 | H26: +4 | I26: 16 | J26: DONE | K26: KC OVER PHI
A27: 13 | B27: William | C27: =picks!AI146 -> 20 | E27: 25 | F27: Jesse | G27: 16 | H27: -16 | I27: 16 | J27: DONE | K27: BAL OVER DET | L27: 15th to 9th to 25th
A28: 5 | B28: Joe | C28: =picks!AI148 -> 25 | E28: 27 | F28: SJay | G28: 15 | H28: -11 | I28: 18 | K28: TEN OVER CHI
A29: 3 | B29: Grant | C29: =picks!AI150 -> 26 | E29: 27 | F29: Bootsie | G29: 15 | H29: -11 | I29: 22 | K29: LAR OVER KC
A30: 13 | B30: Zack | C30: =picks!AI152 -> 20 | E30: 29 | F30: Emjay | G30: 11 | H30: even | I30: 11 | J30: DONE | K30: LAC OVER GB
A31: 6 | B31: Chrissy | C31: =picks!AI154 -> 24 | E31: 29 | F31: Theresa | G31: 11 | H31: -5 | I31: 11 | J31: DONE | K31: SF OVER BUF
G32: =SUM(G2:G31) -> 594
F33: Median score | G33: 20
F34: Average score | G34: =AVERAGE(G32/30) -> 19.8

Sheet picks
A1: Name | D1: SEPT | I1: OCT | N1: NOV | T1: DEC | X1: JAN | Z1: Totals
B2: 4 | C2: 5 | D2: 8 | E2: 14 | F2: 22 | G2: 29 | H2: 5 | I2: 12 | J2: 20 | K2: 26 | L2: 2 | M2: 9 | N2: 13 | O2: 23 | P2: 27 | Q2: 27 | R2: 7 | S2: 11 | T2: 18 | U2: 21 | V2: 25 | W2: tbd | X2: tbd | Y2: tbd
A3: Gm# | B3: 1 | C3: 2 | D3: 3 | E3: 4 | F3: 5 | G3: 6 | H3: 7 | I3: 8 | J3: 9 | K3: 10 | L3: 11 | M3: 12 | N3: 13 | O3: 14 | P3: 15 | Q3: 16 | R3: 17 | S3: 18 | T3: 19 | U3: 20 | V3: 21 | W3: 22 | X3: 23 | Y3: 24 | AB3: PR | AC3: TPP
A4: Lori Lynn | B4: PHI | C4: KC | D4: MIN | E4: LAR | F4: BAL | G4: DEN | H4: IND | I4: PIT | J4: HOU | K4: TB | L4: NYG | M4: BUF | N4: NYJ | O4: JAX | P4: DET | Q4: KC | R4: PIT | S4: TB | T4: LAR | U4: TB | V4: DAL | W4: DEN | X4: JAX | Y4: SEA | Z4: =SUM(B5:Y5) -> 13 | AC4: =SUM(Z4,AB5) -> 13
B5: =IF(B24="Philadelphia Eagles",1,0) -> 1 | C5: =IF(C24="Kansas City Chiefs",1,0) -> 0 | D5: =IF(D24="Minnesota Vikings",1,0) -> 1 | E5: =IF(E24="Los Angeles Rams",1,0) -> 1 | F5: =IF(F24="Baltimore Ravens",1,0) -> 0 | G5: =IF(G24="Denver Broncos",1,0) -> 1 | H5: =IF(H24="Indianapolis Colts",1,0) -> 1 | I5: =IF(I24="Pittsburgh Steelers",1,0) -> 1 | J5: =IF(J24="Houston Texans",1,0) -> 0 | K5: =IF(K24="Tampa Bay Buccaneers",1,0) -> 1 | L5: =IF(L24="New York Giants",1,0) -> 0 | M5: =IF(M24="Buffalo Bills",1,0) -> 0 | N5: =IF(N24="New York Jets",1,0) -> 0 | O5: =IF(O24="Jacksonville Jaguars",1,0) -> 1 | P5: =IF(P24="Detroit Lions",1,0) -> 0 | Q5: =IF(Q24="Kansas City Chiefs",1,0) -> 0 | R5: =IF(R24="Pittsburgh Steelers",1,0) -> 1 | S5: =IF(S24="Tampa Bay Buccaneers",1,0) -> 0 | T5: =IF(T24="Los Angeles Rams",1,0) -> 0 | U5: =IF(U24="Tampa Bay Buccaneers",1,0) -> 0 | V5: =IF(V24="Dallas Cowboys",1,0) -> 1 | W5: =IF(W24="Denver Broncos",1,0) -> 1 | X5: =IF(X24="Jacksonville Jaguars",1,0) -> 1 | Y5: =IF(Y24="Seattle Seahawks",1,0) -> 1
A6: SJay | B6: PHI | C6: LAC | D6: CHI | E6: LAR | F6: BAL | G6: DEN | H6: IND | I6: PIT | J6: HOU | K6: TB | L6: NYG | M6: BUF | N6: NE | O6: ARI | P6: DET | Q6: KC | R6: BAL | S6: TB | T6: LAR | U6: TB | V6: WAS | W6: DEN | X6: TEN | Y6: SF | Z6: =SUM(B7:Y7) -> 9 | AC6: =SUM(Z6,AB7) -> 9
B7: =IF(B24="Philadelphia Eagles",1,0) -> 1 | C7: =IF(C24="Los Angeles Chargers",1,0) -> 1 | D7: =IF(D24="Chicago Bears",1,0) -> 0 | E7: =IF(E24="Los Angeles Rams",1,0) -> 1 | F7: =IF(F24="Baltimore Ravens",1,0) -> 0 | G7: =IF(G24="Denver Broncos",1,0) -> 1 | H7: =IF(H24="Indianapolis Colts",1,0) -> 1 | I7: =IF(I24="Pittsburgh Steelers",1,0) -> 1 | J7: =IF(J24="Houston Texans",1,0) -> 0 | K7: =IF(K24="Tampa Bay Buccaneers",1,0) -> 1 | L7: =IF(L24="New York Giants",1,0) -> 0 | M7: =IF(M24="Buffalo Bills",1,0) -> 0 | N7: =IF(N24="New England Patriots",1,0) -> 1 | O7: =IF(O24="Arizona Cardinals",1,0) -> 0 | P7: =IF(P24="Detroit Lions",1,0) -> 0 | Q7: =IF(Q24="Kansas City Chiefs",1,0) -> 0 | R7: =IF(R24="Baltimore Ravens",1,0) -> 0 | S7: =IF(S24="Tampa Bay Buccaneers",1,0) -> 0 | T7: =IF(T24="Los Angeles Rams",1,0) -> 0 | U7: =IF(U24="Tampa Bay Buccaneers",1,0) -> 0 | V7: =IF(V24="Washington Commanders",1,0) -> 0 | W7: =IF(W24="Denver Broncos",1,0) -> 1 | X7: =IF(X24="Tennessee Titans",1,0) -> 0 | Y7: =IF(Y24="San Francisco 49ers",1,0) -> 0
A8: Boots | B8: PHI | C8: LAC | D8: CHI | E8: TEN | F8: BAL | G8: DEN | H8: IND | I8: PIT | J8: HOU | K8: TB | L8: NYG | M8: BUF | N8: NE | O8: ARI | P8: GB | Q8: KC | R8: BAL | S8: TB | T8: LAR | U8: TB | V8: DAL | W8: DEN | X8: TEN | Y8: SF | Z8: =SUM(B9:Y9) -> 10 | AC8: =SUM(Z8,AB9) -> 10
B9: =IF(B24="Philadelphia Eagles",1,0) -> 1 | C9: =IF(C24="Los Angeles Chargers",1,0) -> 1 | D9: =IF(D24="Chicago Bears",1,0) -> 0 | E9: =IF(E24="Tennessee Titans",1,0) -> 0 | F9: =IF(F24="Baltimore Ravens",1,0) -> 0 | G9: =IF(G24="Denver Broncos",1,0) -> 1 | H9: =IF(H24="Indianapolis Colts",1,0) -> 1 | I9: =IF(I24="Pittsburgh Steelers",1,0) -> 1 | J9: =IF(J24="Houston Texans",1,0) -> 0 | K9: =IF(K24="Tampa Bay Buccaneers",1,0) -> 1 | L9: =IF(L24="New York Giants",1,0) -> 0 | M9: =IF(M24="Buffalo Bills",1,0) -> 0 | N9: =IF(N24="New England Patriots",1,0) -> 1 | O9: =IF(O24="Arizona Cardinals",1,0) -> 0 | P9: =IF(P24="Green Bay Packers",1,0) -> 1 | Q9: =IF(Q24="Kansas City Chiefs",1,0) -> 0 | R9: =IF(R24="Baltimore Ravens",1,0) -> 0 | S9: =IF(S24="Tampa Bay Buccaneers",1,0) -> 0 | T9: =IF(T24="Los Angeles Rams",1,0) -> 0 | U9: =IF(U24="Tampa Bay Buccaneers",1,0) -> 0 | V9: =IF(V24="Dallas Cowboys",1,0) -> 1 | W9: =IF(W24="Denver Broncos",1,0) -> 1 | X9: =IF(X24="Tennessee Titans",1,0) -> 0 | Y9: =IF(Y24="San Francisco 49ers",1,0) -> 0
A10: Colby | B10: PHI | C10: LAC | D10: MIN | E10: LAR | F10: BAL | G10: DEN | H10: LV | I10: PIT | J10: HOU | K10: TB | L10: SF | M10: BUF | N10: NE | O10: ARI | P10: DET | Q10: KC | R10: BAL | S10: TB | T10: LAR | U10: TB | V10: WAS | W10: DEN | X10: JAX | Y10: SF | Z10: =SUM(B11:Y11) -> 11 | AC10: =SUM(Z10,AB11) -> 11
B11: =IF(B24="Philadelphia Eagles",1,0) -> 1 | C11: =IF(C24="Los Angeles Chargers",1,0) -> 1 | D11: =IF(D24="Minnesota Vikings",1,0) -> 1 | E11: =IF(E24="Los Angeles Rams",1,0) -> 1 | F11: =IF(F24="Baltimore Ravens",1,0) -> 0 | G11: =IF(G24="Denver Broncos",1,0) -> 1 | H11: =IF(H24="Las Vegas Raiders",1,0) -> 0 | I11: =IF(I24="Pittsburgh Steelers",1,0) -> 1 | J11: =IF(J24="Houston Texans",1,0) -> 0 | K11: =IF(K24="Tampa Bay Buccaneers",1,0) -> 1 | L11: =IF(L24="San Francisco 49ers",1,0) -> 1 | M11: =IF(M24="Buffalo Bills",1,0) -> 0 | N11: =IF(N24="New England Patriots",1,0) -> 1 | O11: =IF(O24="Arizona Cardinals",1,0) -> 0 | P11: =IF(P24="Detroit Lions",1,0) -> 0 | Q11: =IF(Q24="Kansas City Chiefs",1,0) -> 0 | R11: =IF(R24="Baltimore Ravens",1,0) -> 0 | S11: =IF(S24="Tampa Bay Buccaneers",1,0) -> 0 | T11: =IF(T24="Los Angeles Rams",1,0) -> 0 | U11: =IF(U24="Tampa Bay Buccaneers",1,0) -> 0 | V11: =IF(V24="Washington Commanders",1,0) -> 0 | W11: =IF(W24="Denver Broncos",1,0) -> 1 | X11: =IF(X24="Jacksonville Jaguars",1,0) -> 1 | Y11: =IF(Y24="San Francisco 49ers",1,0) -> 0
A12: Me | B12: PHI | C12: KC | D12: CHI | E12: LAR | F12: BAL | G12: DEN | H12: LV | I12: PIT | J12: HOU | K12: TB | L12: NYG | M12: BUF | N12: NE | O12: ARI | P12: DET | Q12: KC | R12: BAL | S12: TB | T12: LAR | U12: TB | V12: WAS | W12: DEN | X12: JAX | Y12: SF | Z12: =SUM(B13:Y13) -> 8 | AC12: =SUM(Z12,AB13) -> 8
B13: =IF(B24="Philadelphia Eagles",1,0) -> 1 | C13: =IF(C24="Kansas City Chiefs",1,0) -> 0 | D13: =IF(D24="Chicago Bears",1,0) -> 0 | E13: =IF(E24="Los Angeles Rams",1,0) -> 1 | F13: =IF(F24="Baltimore Ravens",1,0) -> 0 | G13: =IF(G24="Denver Broncos",1,0) -> 1 | H13: =IF(H24="Las Vegas Raiders",1,0) -> 0 | I13: =IF(I24="Pittsburgh Steelers",1,0) -> 1 | J13: =IF(J24="Houston Texans",1,0) -> 0 | K13: =IF(K24="Tampa Bay Buccaneers",1,0) -> 1 | L13: =IF(L24="New York Giants",1,0) -> 0 | M13: =IF(M24="Buffalo Bills",1,0) -> 0 | N13: =IF(N24="New England Patriots",1,0) -> 1 | O13: =IF(O24="Arizona Cardinals",1,0) -> 0 | P13: =IF(P24="Detroit Lions",1,0) -> 0 | Q13: =IF(Q24="Kansas City Chiefs",1,0) -> 0 | R13: =IF(R24="Baltimore Ravens",1,0) -> 0 | S13: =IF(S24="Tampa Bay Buccaneers",1,0) -> 0 | T13: =IF(T24="Los Angeles Rams",1,0) -> 0 | U13: =IF(U24="Tampa Bay Buccaneers",1,0) -> 0 | V13: =IF(V24="Washington Commanders",1,0) -> 0 | W13: =IF(W24="Denver Broncos",1,0) -> 1 | X13: =IF(X24="Jacksonville Jaguars",1,0) -> 1 | Y13: =IF(Y24="San Francisco 49ers",1,0) -> 0
A14: Shelley | B14: PHI | C14: LAC | D14: MIN | E14: LAR | F14: BAL | G14: DEN | H14: IND | I14: PIT | J14: SEA | K14: NO | L14: SF | M14: BUF | N14: NE | O14: ARI | P14: DET | Q14: DAL | R14: BAL | S14: TB | T14: SEA | U14: TB | V14: DAL | W14: LAC | X14: JAX | Y14: SEA | Z14: =SUM(B15:Y15) -> 15 | AC14: =SUM(Z14,AB15) -> 15
B15: =IF(B24="Philadelphia Eagles",1,0) -> 1 | C15: =IF(C24="Los Angeles Chargers",1,0) -> 1 | D15: =IF(D24="Minnesota Vikings",1,0) -> 1 | E15: =IF(E24="Los Angeles Rams",1,0) -> 1 | F15: =IF(F24="Baltimore Ravens",1,0) -> 0 | G15: =IF(G24="Denver Broncos",1,0) -> 1 | H15: =IF(H24="Indianapolis Colts",1,0) -> 1 | I15: =IF(I24="Pittsburgh Steelers",1,0) -> 1 | J15: =IF(J24="Seattle Seahawks",1,0) -> 1 | K15: =IF(K24="New Orleans Saints",1,0) -> 0 | L15: =IF(L24="San Francisco 49ers",1,0) -> 1 | M15: =IF(M24="Buffalo Bills",1,0) -> 0 | N15: =IF(N24="New England Patriots",1,0) -> 1 | O15: =IF(O24="Arizona Cardinals",1,0) -> 0 | P15: =IF(P24="Detroit Lions",1,0) -> 0 | Q15: =IF(Q24="Dallas Cowboys",1,0) -> 1 | R15: =IF(R24="Baltimore Ravens",1,0) -> 0 | S15: =IF(S24="Tampa Bay Buccaneers",1,0) -> 0 | T15: =IF(T24="Seattle Seahawks",1,0) -> 1 | U15: =IF(U24="Tampa Bay Buccaneers",1,0) -> 0 | V15: =IF(V24="Dallas Cowboys",1,0) -> 1 | W15: =IF(W24="Los Angeles Chargers",1,0) -> 0 | X15: =IF(X24="Jacksonville Jaguars",1,0) -> 1 | Y15: =IF(Y24="Seattle Seahawks",1,0) -> 1
A16: Brian | B16: PHI | C16: KC | D16: MIN | E16: LAR | F16: DET | G16: DEN | H16: LV | I16: PIT | J16: SEA | K16: TB | L16: NYG | M16: MIA | N16: NE | O16: ARI | P16: DET | Q16: KC | R16: BAL | S16: ATL | T16: LAR | U16: CAR | V16: DAL | W16: DEN | X16: JAX | Y16: SF | Z16: =SUM(B17:Y17) -> 15 | AC16: =SUM(Z16,AB17) -> 15
B17: =IF(B24="Philadelphia Eagles",1,0) -> 1 | C17: =IF(C24="Kansas City Chiefs",1,0) -> 0 | D17: =IF(D24="Minnesota Vikings",1,0) -> 1 | E17: =IF(E24="Los Angeles Rams",1,0) -> 1 | F17: =IF(F24="Detroit Lions",1,0) -> 1 | G17: =IF(G24="Denver Broncos",1,0) -> 1 | H17: =IF(H24="Las Vegas Raiders",1,0) -> 0 | I17: =IF(I24="Pittsburgh Steelers",1,0) -> 1 | J17: =IF(J24="Seattle Seahawks",1,0) -> 1 | K17: =IF(K24="Tampa Bay Buccaneers",1,0) -> 1 | L17: =IF(L24="New York Giants",1,0) -> 0 | M17: =IF(M24="Miami Dolphins",1,0) -> 1 | N17: =IF(N24="New England Patriots",1,0) -> 1 | O17: =IF(O24="Arizona Cardinals",1,0) -> 0 | P17: =IF(P24="Detroit Lions",1,0) -> 0 | Q17: =IF(Q24="Kansas City Chiefs",1,0) -> 0 | R17: =IF(R24="Baltimore Ravens",1,0) -> 0 | S17: =IF(S24="Atlanta Falcons",1,0) -> 1 | T17: =IF(T24="Los Angeles Rams",1,0) -> 0 | U17: =IF(U24="Carolina Panthers",1,0) -> 1 | V17: =IF(V24="Dallas Cowboys",1,0) -> 1 | W17: =IF(W24="Denver Broncos",1,0) -> 1 | X17: =IF(X24="Jacksonville Jaguars",1,0) -> 1 | Y17: =IF(Y24="San Francisco 49ers",1,0) -> 0
A18: Bloomers | B18: PHI | C18: KC | D18: MIN | E18: TEN | F18: BAL | G18: DEN | H18: LV | I18: PIT | J18: SEA | K18: TB | L18: NYG | M18: BUF | N18: NYJ | O18: JAX | P18: DET | Q18: KC | R18: BAL | S18: TB | T18: LAR | U18: TB | V18: WAS | W18: LAC | X18: JAX | Y18: SEA | Z18: =SUM(B19:Y19) -> 9 | AC18: =SUM(Z18,AB19) -> 9
B19: =IF(B24="Philadelphia Eagles",1,0) -> 1 | C19: =IF(C24="Kansas City Chiefs",1,0) -> 0 | D19: =IF(D24="Minnesota Vikings",1,0) -> 1 | E19: =IF(E24="Tennessee Titans",1,0) -> 0 | F19: =IF(F24="Baltimore Ravens",1,0) -> 0 | G19: =IF(G24="Denver Broncos",1,0) -> 1 | H19: =IF(H24="Las Vegas Raiders",1,0) -> 0 | I19: =IF(I24="Pittsburgh Steelers",1,0) -> 1 | J19: =IF(J24="Seattle Seahawks",1,0) -> 1 | K19: =IF(K24="Tampa Bay Buccaneers",1,0) -> 1 | L19: =IF(L24="New York Giants",1,0) -> 0 | M19: =IF(M24="Buffalo Bills",1,0) -> 0 | N19: =IF(N24="New York Jets",1,0) -> 0 | O19: =IF(O24="Jacksonville Jaguars",1,0) -> 1 | P19: =IF(P24="Detroit Lions",1,0) -> 0 | Q19: =IF(Q24="Kansas City Chiefs",1,0) -> 0 | R19: =IF(R24="Baltimore Ravens",1,0) -> 0 | S19: =IF(S24="Tampa Bay Buccaneers",1,0) -> 0 | T19: =IF(T24="Los Angeles Rams",1,0) -> 0 | U19: =IF(U24="Tampa Bay Buccaneers",1,0) -> 0 | V19: =IF(V24="Washington Commanders",1,0) -> 0 | W19: =IF(W24="Los Angeles Chargers",1,0) -> 0 | X19: =IF(X24="Jacksonville Jaguars",1,0) -> 1 | Y19: =IF(Y24="Seattle Seahawks",1,0) -> 1
A20: Tom | B20: PHI | C20: KC | D20: CHI | E20: LAR | F20: BAL | G20: DEN | H20: IND | I20: PIT | J20: HOU | K20: TB | L20: SF | M20: BUF | N20: NE | O20: ARI | P20: DET | Q20: KC | R20: BAL | S20: TB | T20: LAR | U20: TB | V20: WAS | W20: DEN | X20: JAX | Y20: SF | Z20: =SUM(B21:Y21) -> 10 | AC20: =SUM(Z20,AB21) -> 10
B21: =IF(B24="Philadelphia Eagles",1,0) -> 1 | C21: =IF(C24="Kansas City Chiefs",1,0) -> 0 | D21: =IF(D24="Chicago Bears",1,0) -> 0 | E21: =IF(E24="Los Angeles Rams",1,0) -> 1 | F21: =IF(F24="Baltimore Ravens",1,0) -> 0 | G21: =IF(G24="Denver Broncos",1,0) -> 1 | H21: =IF(H24="Indianapolis Colts",1,0) -> 1 | I21: =IF(I24="Pittsburgh Steelers",1,0) -> 1 | J21: =IF(J24="Houston Texans",1,0) -> 0 | K21: =IF(K24="Tampa Bay Buccaneers",1,0) -> 1 | L21: =IF(L24="San Francisco 49ers",1,0) -> 1 | M21: =IF(M24="Buffalo Bills",1,0) -> 0 | N21: =IF(N24="New England Patriots",1,0) -> 1 | O21: =IF(O24="Arizona Cardinals",1,0) -> 0 | P21: =IF(P24="Detroit Lions",1,0) -> 0 | Q21: =IF(Q24="Kansas City Chiefs",1,0) -> 0 | R21: =IF(R24="Baltimore Ravens",1,0) -> 0 | S21: =IF(S24="Tampa Bay Buccaneers",1,0) -> 0 | T21: =IF(T24="Los Angeles Rams",1,0) -> 0 | U21: =IF(U24="Tampa Bay Buccaneers",1,0) -> 0 | V21: =IF(V24="Washington Commanders",1,0) -> 0 | W21: =IF(W24="Denver Broncos",1,0) -> 1 | X21: =IF(X24="Jacksonville Jaguars",1,0) -> 1 | Y21: =IF(Y24="San Francisco 49ers",1,0) -> 0
A22: Karen | B22: PHI | C22: KC | D22: MIN | E22: TEN | F22: BAL | G22: CIN | H22: LV | I22: PIT | J22: SEA | K22: NO | L22: SF | M22: BUF | N22: NE | O22: JAX | P22: GB | Q22: KC | R22: BAL | S22: TB | T22: SEA | U22: CAR | V22: WAS | W22: LAC | X22: TEN | Y22: SF | Z22: =SUM(B23:Y23) -> 10 | AC22: =SUM(Z22,AB23) -> 10
B23: =IF(B24="Philadelphia Eagles",1,0) -> 1 | C23: =IF(C24="Kansas City Chiefs",1,0) -> 0 | D23: =IF(D24="Minnesota Vikings",1,0) -> 1 | E23: =IF(E24="Tennessee Titans",1,0) -> 0 | F23: =IF(F24="Baltimore Ravens",1,0) -> 0 | G23: =IF(G24="Cincinnati Bengals",1,0) -> 0 | H23: =IF(H24="Las Vegas Raiders",1,0) -> 0 | I23: =IF(I24="Pittsburgh Steelers",1,0) -> 1 | J23: =IF(J24="Seattle Seahawks",1,0) -> 1 | K23: =IF(K24="New Orleans Saints",1,0) -> 0 | L23: =IF(L24="San Francisco 49ers",1,0) -> 1 | M23: =IF(M24="Buffalo Bills",1,0) -> 0 | N23: =IF(N24="New England Patriots",1,0) -> 1 | O23: =IF(O24="Jacksonville Jaguars",1,0) -> 1 | P23: =IF(P24="Green Bay Packers",1,0) -> 1 | Q23: =IF(Q24="Kansas City Chiefs",1,0) -> 0 | R23: =IF(R24="Baltimore Ravens",1,0) -> 0 | S23: =IF(S24="Tampa Bay Buccaneers",1,0) -> 0 | T23: =IF(T24="Seattle Seahawks",1,0) -> 1 | U23: =IF(U24="Carolina Panthers",1,0) -> 1 | V23: =IF(V24="Washington Commanders",1,0) -> 0 | W23: =IF(W24="Los Angeles Chargers",1,0) -> 0 | X23: =IF(X24="Tennessee Titans",1,0) -> 0 | Y23: =IF(Y24="San Francisco 49ers",1,0) -> 0
A24: Winners | B24: Philadelphia Eagles | C24: Los Angeles Chargers | D24: Minnesota Vikings | E24: Los Angeles Rams | F24: Detroit Lions | G24: Denver Broncos | H24: Indianapolis Colts | I24: Pittsburgh Steelers | J24: Seattle Seahawks | K24: Tampa Bay Buccaneers | L24: San Francisco 49ers | M24: Miami Dolphins | N24: New England Patriots | O24: Jacksonville Jaguars | P24: Green Bay Packers | Q24: Dallas Cowboys | R24: Pittsburgh Steelers | S24: Atlanta Falcons | T24: Seattle Seahawks | U24: Carolina Panthers | V24: Dallas Cowboys | W24: Denver Broncos | X24: Jacksonville Jaguars | Y24: Seattle Seahawks
A28: NAME | B28: Divisional winners (2 pts each) | L28: Wildcard teams (3 pts each) | T28: Superbowl (3 pts) | X28: Superbowl Champ (4 pts) | AE28: Playoffs Total | AG28: Regular Season Total | AI28: TOTALITY | AL28: Max Score
B29: AFC | G29: NFC | L29: AFC | P29: NFC | T29: AFC | V29: NFC | AB29: PR | AR29: Notes
B30: E | C30: N | D30: S | E30: W | G30: E | H30: N | I30: S | J30: W | AA30: SB | AC30: TPR
A31: Lori Lynn | B31: BUF | C31: PIT | D31: IND | E31: KC | G31: PHI | H31: MIN | I31: TB | J31: LAR | L31: MIA | M31: HOU | N31: DEN | P31: DET | Q31: ATL | R31: SEA | T31: BUF | V31: PHI | X31: BUF | AE31: =SUM(B32,C32,D32,E32,G32,H32,I32,J32,L32,M32,N32,P32,R32,Q32,T32,V32,X32) -> 7 | AG31: =Z4 -> 13 | AI31: =SUM(AE31,AG31) -> 20 | AM31: =SUM(AC32,AI31) -> 20
B32: X | C32: 2 | D32: X | E32: X | G32: 2 | H32: X | I32: X | J32: X | K32: 0 | L32: X | M32: 3 | N32: X | O32: 0 | P32: X | Q32: X | R32: X | S32: 0 | T32: X | V32: X | X32: X | AA32: 0 | AB32: =SUM(K32,O32,S32,AA32) -> 0 | AC32: =SUM(AB5,AB32) -> 0
A33: SJay | B33: BUF | C33: PIT | D33: HOU | E33: KC | G33: PHI | H33: CHI | I33: TB | J33: LAR | L33: NE | M33: TEN | N33: DEN | P33: NYG | Q33: MIN | R33: ARI | T33: TEN | V33: CHI | X33: TEN | AE33: =SUM(B34,C34,D34,E34,G34,H34,I34,J34,L34,M34,N34,P34,Q34,R34,T34,V34,X34) -> 6 | AG33: =Z6 -> 9 | AI33: =SUM(AE33,AG33) -> 15 | AM33: =SUM(AC34,AI33) -> 18 | AR33: Eliminated, not done
B34: X | C34: 2 | D34: X | E34: X | G34: 2 | H34: 2 | I34: X | J34: X | K34: 0 | L34: X | M34: X | N34: X | O34: 0 | P34: X | Q34: X | R34: X | S34: 0 | T34: X | X34: X | AA34: 3 | AB34: =SUM(K34,O34,S34,AA34) -> 3 | AC34: =SUM(AB7,AB34) -> 3
A35: Boots | B35: BUF | C35: BAL | D35: TEN | E35: KC | G35: NYG | H35: CHI | I35: TB | J35: ARI | L35: NE | M35: PIT | N35: DEN | P35: PHI | Q35: MIN | R35: LAR | T35: KC | V35: LAR | X35: LAR | AE35: =SUM(B36,C36,D36,E36,G36,H36,I36,J36,L36,M36,N36,P36,Q36,R36,T36,V36,X36) -> 5 | AG35: =Z8 -> 10 | AI35: =SUM(AE35,AG35) -> 15 | AM35: =SUM(AC36,AI35) -> 22 | AR35: Eliminated, not done
B36: X | C36: X | D36: X | E36: X | G36: X | H36: 2 | I36: X | J36: X | K36: 0 | L36: X | M36: X | N36: X | O36: 0 | P36: X | Q36: X | R36: 3 | S36: 0 | T36: X | AA36: 7 | AB36: =SUM(K36,O36,S36,AA36) -> 7 | AC36: =SUM(AB9,AB36) -> 7
A37: Colby | B37: BUF | C37: BAL | D37: HOU | E37: DEN | G37: PHI | H37: DET | I37: TB | J37: LAR | L37: KC | M37: CIN | N37: LAC | P37: SEA | Q37: GB | R37: WAS | T37: BAL | V37: PHI | X37: BAL | AE37: =SUM(B38,C38,D38,E38,G38,H38,I38,J38,L38,M38,N38,P38,R38,Q38,T38,V38,X38) -> 10 | AG37: =Z10 -> 11 | AI37: =SUM(AE37,AG37) -> 21 | AM37: =SUM(AC38,AI37) -> 21 | AR37: DONE - 21
B38: X | C38: X | D38: X | E38: 2 | G38: 2 | H38: X | I38: X | J38: X | K38: 0 | L38: X | M38: X | N38: 3 | O38: 0 | P38: X | Q38: 3 | R38: X | S38: 0 | T38: X | V38: X | X38: X | AA38: 0 | AB38: =SUM(K38,O38,S38,AA38) -> 0 | AC38: =SUM(AB11,AB38) -> 0
A39: Me | B39: BUF | C39: BAL | D39: HOU | E39: KC | G39: WAS | H39: GB | I39: TB | J39: LAR | L39: LAC | M39: DEN | N39: PIT | P39: PHI | Q39: DET | R39: ARI | T39: LAC | V39: GB | X39: LAC | AE39: =SUM(B40,C40,D40,E40,G40,H40,I40,J40,L40,M40,N40,P40,Q40,R40,T40,V40,X40) -> 3 | AG39: =Z12 -> 8 | AI39: =SUM(AE39,AG39) -> 11 | AM39: =SUM(AC40,AI39) -> 11 | AR39: DONE - 11
B40: X | C40: X | D40: X | E40: X | G40: X | H40: X | I40: X | J40: X | K40: 0 | L40: 3 | M40: X | N40: X | O40: 0 | P40: X | Q40: X | R40: X | S40: 0 | T40: X | V40: X | X40: X | AA40: 0 | AB40: =SUM(K40,O40,S40,AA40) -> 0 | AC40: =SUM(AB13,AB40) -> 0
A41: Shelley | B41: BUF | C41: BAL | D41: HOU | E41: LAC | G41: PHI | H41: DET | I41: ATL | J41: SEA | L41: PIT | M41: KC | N41: DEN | P41: MIN | Q41: LAR | R41: DAL | T41: BUF | V41: SEA | X41: BUF | AE41: =SUM(B42,C42,D42,E42,G42,H42,I42,J42,L42,M42,N42,P42,R42,Q42,T42,V42,X42) -> 7 | AG41: =Z14 -> 15 | AI41: =SUM(AE41,AG41) -> 22 | AM41: =SUM(AC42,AI41) -> 25 | AR41: Eliminated, not done
B42: X | C42: X | D42: X | E42: X | G42: 2 | H42: X | I42: X | J42: 2 | K42: 0 | L42: X | M42: X | N42: X | O42: 0 | P42: X | Q42: 3 | R42: X | S42: 0 | T42: X | X42: X | AA42: 3 | AB42: =SUM(K42,O42,S42,AA42) -> 3 | AC42: =SUM(AB15,AB42) -> 3
A43: Brian | B43: NE | C43: PIT | D43: HOU | E43: KC | G43: DAL | H43: MIN | I43: TB | J43: LAR | L43: BAL | M43: BUF | N43: LAC | P43: PHI | Q43: DET | R43: SF | T43: BUF | V43: PHI | X43: BUF | AE43: =SUM(B44,C44,D44,E44,G44,H44,I44,J44,L44,M44,N44,P44,Q44,R44,T44,V44,X44) -> 13 | AG43: =Z16 -> 15 | AI43: =SUM(AE43,AG43) -> 28 | AM43: =SUM(AC44,AI43) -> 28 | AR43: 1ST PLACE
...

Sheet team names
A1: full team names to be used for winners on rows 25, 74, and 123 on main | B1: Eliminated
A2: Arizona Cardinals | B2: 1
A3: Atlanta Falcons | B3: 1
A4: Baltimore Ravens
A5: Buffalo Bills
A6: Carolina Panthers
A7: Chicago Bears
A8: Cincinnati Bengals | B8: 1
A9: Cleveland Browns | B9: 1
A10: Dallas Cowboys | B10: 1
A11: Denver Broncos
A12: Detroit Lions | B12: 1
A13: Green Bay Packers
A14: Houston Texans
A15: Indianapolis Colts | B15: 1
A16: Jacksonville Jaguars
A17: Kansas City Chiefs | B17: 1
A18: Las Vegas Raiders | B18: 1
A19: Los Angeles Chargers
A20: Los Angeles Rams
A21: Miami Dolphins | B21: 1
A22: Minnesota Vikings | B22: 1
A23: New England Patriots
A24: New Orleans Saints | B24: 1
A25: New York Giants | B25: 1
A26: New York Jets | B26: 1
A27: Philadelphia Eagles
A28: Pittsburgh Steelers
A29: San Francisco 49ers
A30: Seattle Seahawks
A31: Tampa Bay Buccaneers
A32: Tennessee Titans | B32: 1
A33: Washington Commanders | B33: 1
B34: =SUM(B2:B33) -> 16
